2020-09-28 13:41:35 [Command Error] User: "Ahnaf#4346", Message: "sh!wrong", Error: "ZeroDivisionError: division by zero", Traceback: "Traceback (most recent call last):  File "C:\Users\HOME\AppData\Local\Programs\Python\Python38-32\lib\site-packages\lightbulb\command_handler.py", line 852, in process_commands_for_event    await self._invoke_command(command, context, positional_args, keyword_arg)  File "C:\Users\HOME\AppData\Local\Programs\Python\Python38-32\lib\site-packages\lightbulb\command_handler.py", line 788, in _invoke_command    await command.invoke(context)  File "C:\Users\HOME\AppData\Local\Programs\Python\Python38-32\lib\site-packages\lightbulb\commands.py", line 495, in invoke    return await self._callback(context, *new_args, **kwargs)  File "F:\Ahnaf's Folder\Shikamaru Bot\shikamaru\bot.py", line 20, in wrong    await ctx.reply(1/0)lightbulb.errors.CommandInvocationError: ZeroDivisionError: division by zero"
2020-09-28 14:59:13 [Command Error] User: "Ahnaf#4346", Message: "sh!github", Error: "github", Traceback: "Traceback (most recent call last):  File "C:\Users\HOME\AppData\Local\Programs\Python\Python38-32\lib\site-packages\lightbulb\command_handler.py", line 840, in process_commands_for_event    positional_args, keyword_arg = self.resolve_args_for_command(command, final_args)  File "C:\Users\HOME\AppData\Local\Programs\Python\Python38-32\lib\site-packages\lightbulb\command_handler.py", line 768, in resolve_args_for_command    raise errors.NotEnoughArguments(command.name)lightbulb.errors.NotEnoughArguments: github"
2020-09-28 15:01:00 [Command Error] User: "Ahnaf#4346", Message: "sh!help github", Error: "AttributeError: 'str' object has no attribute 'annotation'", Traceback: "Traceback (most recent call last):  File "C:\Users\HOME\AppData\Local\Programs\Python\Python38-32\lib\site-packages\lightbulb\command_handler.py", line 852, in process_commands_for_event    await self._invoke_command(command, context, positional_args, keyword_arg)  File "C:\Users\HOME\AppData\Local\Programs\Python\Python38-32\lib\site-packages\lightbulb\command_handler.py", line 788, in _invoke_command    await command.invoke(context)  File "C:\Users\HOME\AppData\Local\Programs\Python\Python38-32\lib\site-packages\lightbulb\commands.py", line 495, in invoke    return await self._callback(context, *new_args, **kwargs)  File "C:\Users\HOME\AppData\Local\Programs\Python\Python38-32\lib\site-packages\lightbulb\help.py", line 124, in _help_cmd    await ctx.bot.help_command.resolve_help_obj(ctx, obj)  File "C:\Users\HOME\AppData\Local\Programs\Python\Python38-32\lib\site-packages\lightbulb\help.py", line 181, in resolve_help_obj    await self.send_command_help(context, command)  File "F:\Ahnaf's Folder\Shikamaru Bot\shikamaru\plugins\help.py", line 23, in send_command_help    print([i.annotation.__name__ for i in command.arg_details.args])  File "F:\Ahnaf's Folder\Shikamaru Bot\shikamaru\plugins\help.py", line 23, in <listcomp>    print([i.annotation.__name__ for i in command.arg_details.args])lightbulb.errors.CommandInvocationError: AttributeError: 'str' object has no attribute 'annotation'"
2020-09-28 15:31:18 [Command Error] User: "Ahnaf#4346", Message: "sh!help github", Error: "TypeError: __init__() got an unexpected keyword argument 'name'", Traceback: "Traceback (most recent call last):  File "C:\Users\HOME\AppData\Local\Programs\Python\Python38-32\lib\site-packages\lightbulb\command_handler.py", line 852, in process_commands_for_event    await self._invoke_command(command, context, positional_args, keyword_arg)  File "C:\Users\HOME\AppData\Local\Programs\Python\Python38-32\lib\site-packages\lightbulb\command_handler.py", line 788, in _invoke_command    await command.invoke(context)  File "C:\Users\HOME\AppData\Local\Programs\Python\Python38-32\lib\site-packages\lightbulb\commands.py", line 495, in invoke    return await self._callback(context, *new_args, **kwargs)  File "C:\Users\HOME\AppData\Local\Programs\Python\Python38-32\lib\site-packages\lightbulb\help.py", line 124, in _help_cmd    await ctx.bot.help_command.resolve_help_obj(ctx, obj)  File "C:\Users\HOME\AppData\Local\Programs\Python\Python38-32\lib\site-packages\lightbulb\help.py", line 181, in resolve_help_obj    await self.send_command_help(context, command)  File "F:\Ahnaf's Folder\Shikamaru Bot\shikamaru\plugins\help.py", line 23, in send_command_help    em = hikari.Embed(name=f"Help for: {command.name.capitalize()}", color="#ae00ff" )lightbulb.errors.CommandInvocationError: TypeError: __init__() got an unexpected keyword argument 'name'"
2020-09-28 15:32:22 [Command Error] User: "Forbidden#0001", Message: "sh!github", Error: "github", Traceback: "Traceback (most recent call last):  File "C:\Users\HOME\AppData\Local\Programs\Python\Python38-32\lib\site-packages\lightbulb\command_handler.py", line 840, in process_commands_for_event    positional_args, keyword_arg = self.resolve_args_for_command(command, final_args)  File "C:\Users\HOME\AppData\Local\Programs\Python\Python38-32\lib\site-packages\lightbulb\command_handler.py", line 768, in resolve_args_for_command    raise errors.NotEnoughArguments(command.name)lightbulb.errors.NotEnoughArguments: github"
2020-09-28 15:47:40 [Command Error] User: "Ahnaf#4346", Message: "sh!exec
```py
print("Oof")
```", Error: "You are not the owner of this bot", Traceback: "Traceback (most recent call last):  File "C:\Users\HOME\AppData\Local\Programs\Python\Python38-32\lib\site-packages\lightbulb\command_handler.py", line 841, in process_commands_for_event    await self._evaluate_checks(command, context)  File "C:\Users\HOME\AppData\Local\Programs\Python\Python38-32\lib\site-packages\lightbulb\command_handler.py", line 685, in _evaluate_checks    raise failed_checks[0]  File "C:\Users\HOME\AppData\Local\Programs\Python\Python38-32\lib\site-packages\lightbulb\command_handler.py", line 673, in _evaluate_checks    if not await check(context):  File "C:\Users\HOME\AppData\Local\Programs\Python\Python38-32\lib\site-packages\lightbulb\checks.py", line 93, in _owner_only    raise errors.NotOwner("You are not the owner of this bot")lightbulb.errors.NotOwner: You are not the owner of this bot"
2020-09-28 15:50:10 [Command Error] User: "Ahnaf#4346", Message: "sh!exec
```py
print("Oof")
```", Error: "AttributeError: 'SuperUser' object has no attribute 'logger'", Traceback: "Traceback (most recent call last):  File "C:\Users\HOME\AppData\Local\Programs\Python\Python38-32\lib\site-packages\lightbulb\command_handler.py", line 852, in process_commands_for_event    await self._invoke_command(command, context, positional_args, keyword_arg)  File "C:\Users\HOME\AppData\Local\Programs\Python\Python38-32\lib\site-packages\lightbulb\command_handler.py", line 784, in _invoke_command    await command.invoke(context, *args, **kwarg)  File "C:\Users\HOME\AppData\Local\Programs\Python\Python38-32\lib\site-packages\lightbulb\commands.py", line 88, in invoke    return await self._callback(instance, context, *new_args, **kwargs)  File "F:\Ahnaf's Folder\Shikamaru Bot\shikamaru\plugins\superuser.py", line 22, in execute    await body.run()  File "F:\Ahnaf's Folder\Shikamaru Bot\shikamaru\utils\code.py", line 46, in _execute    if logger := getattr(self.context.command.plugin, "logger"):lightbulb.errors.CommandInvocationError: AttributeError: 'SuperUser' object has no attribute 'logger'"
2020-09-28 15:50:28 [Command Error] User: "Ahnaf#4346", Message: "sh!exec
```py
print("Oof")
```", Error: "AttributeError: 'SuperUser' object has no attribute 'logger'", Traceback: "Traceback (most recent call last):  File "C:\Users\HOME\AppData\Local\Programs\Python\Python38-32\lib\site-packages\lightbulb\command_handler.py", line 852, in process_commands_for_event    await self._invoke_command(command, context, positional_args, keyword_arg)  File "C:\Users\HOME\AppData\Local\Programs\Python\Python38-32\lib\site-packages\lightbulb\command_handler.py", line 784, in _invoke_command    await command.invoke(context, *args, **kwarg)  File "C:\Users\HOME\AppData\Local\Programs\Python\Python38-32\lib\site-packages\lightbulb\commands.py", line 88, in invoke    return await self._callback(instance, context, *new_args, **kwargs)  File "F:\Ahnaf's Folder\Shikamaru Bot\shikamaru\plugins\superuser.py", line 22, in execute    await body.run()  File "F:\Ahnaf's Folder\Shikamaru Bot\shikamaru\utils\code.py", line 46, in _execute    if logger := getattr(self.context.command.plugin, "logger"):lightbulb.errors.CommandInvocationError: AttributeError: 'SuperUser' object has no attribute 'logger'"
2020-09-28 15:53:54 [Command Error] User: "Ahnaf#4346", Message: "sh!codefor SuperUser", Error: "NameError: name 'Plugin' is not defined", Traceback: "Traceback (most recent call last):  File "C:\Users\HOME\AppData\Local\Programs\Python\Python38-32\lib\site-packages\lightbulb\command_handler.py", line 852, in process_commands_for_event    await self._invoke_command(command, context, positional_args, keyword_arg)  File "C:\Users\HOME\AppData\Local\Programs\Python\Python38-32\lib\site-packages\lightbulb\command_handler.py", line 786, in _invoke_command    await command.invoke(context, *args)  File "C:\Users\HOME\AppData\Local\Programs\Python\Python38-32\lib\site-packages\lightbulb\commands.py", line 88, in invoke    return await self._callback(instance, context, *new_args, **kwargs)  File "F:\Ahnaf's Folder\Shikamaru Bot\shikamaru\plugins\superuser.py", line 71, in getcode    if isinstance(child, Plugin)lightbulb.errors.CommandInvocationError: NameError: name 'Plugin' is not defined"
2020-09-28 15:55:19 [Command Error] User: "Ahnaf#4346", Message: "sh!exec
```py
print()
```", Error: "AttributeError: 'SuperUser' object has no attribute 'logger'", Traceback: "Traceback (most recent call last):  File "C:\Users\HOME\AppData\Local\Programs\Python\Python38-32\lib\site-packages\lightbulb\command_handler.py", line 852, in process_commands_for_event    await self._invoke_command(command, context, positional_args, keyword_arg)  File "C:\Users\HOME\AppData\Local\Programs\Python\Python38-32\lib\site-packages\lightbulb\command_handler.py", line 784, in _invoke_command    await command.invoke(context, *args, **kwarg)  File "C:\Users\HOME\AppData\Local\Programs\Python\Python38-32\lib\site-packages\lightbulb\commands.py", line 88, in invoke    return await self._callback(instance, context, *new_args, **kwargs)  File "F:\Ahnaf's Folder\Shikamaru Bot\shikamaru\plugins\superuser.py", line 22, in execute    await body.run()  File "F:\Ahnaf's Folder\Shikamaru Bot\shikamaru\utils\code.py", line 46, in _execute    if logger := getattr(self.context.command.plugin, "logger"):lightbulb.errors.CommandInvocationError: AttributeError: 'SuperUser' object has no attribute 'logger'"
2020-09-28 16:03:52 [Command Error] User: "Ahnaf#4346", Message: "sh!exec
```py
print()
```", Error: "NameError: name 'command' is not defined", Traceback: "Traceback (most recent call last):  File "C:\Users\HOME\AppData\Local\Programs\Python\Python38-32\lib\site-packages\lightbulb\command_handler.py", line 852, in process_commands_for_event    await self._invoke_command(command, context, positional_args, keyword_arg)  File "C:\Users\HOME\AppData\Local\Programs\Python\Python38-32\lib\site-packages\lightbulb\command_handler.py", line 788, in _invoke_command    await command.invoke(context)  File "C:\Users\HOME\AppData\Local\Programs\Python\Python38-32\lib\site-packages\lightbulb\commands.py", line 88, in invoke    return await self._callback(instance, context, *new_args, **kwargs)  File "F:\Ahnaf's Folder\Shikamaru Bot\shikamaru\plugins\superuser.py", line 23, in code    code = ctx.message.content[len(command) + 1:]lightbulb.errors.CommandInvocationError: NameError: name 'command' is not defined"
2020-09-28 16:06:17 [Command Error] User: "Ahnaf#4346", Message: "sh!exec
```py
print()
```", Error: "AttributeError: 'SuperUser' object has no attribute 'eprint'", Traceback: "Traceback (most recent call last):  File "C:\Users\HOME\AppData\Local\Programs\Python\Python38-32\lib\site-packages\lightbulb\command_handler.py", line 852, in process_commands_for_event    await self._invoke_command(command, context, positional_args, keyword_arg)  File "C:\Users\HOME\AppData\Local\Programs\Python\Python38-32\lib\site-packages\lightbulb\command_handler.py", line 788, in _invoke_command    await command.invoke(context)  File "C:\Users\HOME\AppData\Local\Programs\Python\Python38-32\lib\site-packages\lightbulb\commands.py", line 88, in invoke    return await self._callback(instance, context, *new_args, **kwargs)  File "F:\Ahnaf's Folder\Shikamaru Bot\shikamaru\plugins\superuser.py", line 39, in code    "eprint": self.eprint,lightbulb.errors.CommandInvocationError: AttributeError: 'SuperUser' object has no attribute 'eprint'"
2020-09-28 16:08:02 [Command Error] User: "Ahnaf#4346", Message: "sh!exec
```py
print()
```", Error: "NameError: name 'io' is not defined", Traceback: "Traceback (most recent call last):  File "C:\Users\HOME\AppData\Local\Programs\Python\Python38-32\lib\site-packages\lightbulb\command_handler.py", line 852, in process_commands_for_event    await self._invoke_command(command, context, positional_args, keyword_arg)  File "C:\Users\HOME\AppData\Local\Programs\Python\Python38-32\lib\site-packages\lightbulb\command_handler.py", line 788, in _invoke_command    await command.invoke(context)  File "C:\Users\HOME\AppData\Local\Programs\Python\Python38-32\lib\site-packages\lightbulb\commands.py", line 88, in invoke    return await self._callback(instance, context, *new_args, **kwargs)  File "F:\Ahnaf's Folder\Shikamaru Bot\shikamaru\plugins\superuser.py", line 46, in code    stdout = io.StringIO()lightbulb.errors.CommandInvocationError: NameError: name 'io' is not defined"
2020-09-28 16:10:59 [Command Error] User: "Ahnaf#4346", Message: "sh!exec
```py
print()
```", Error: "AttributeError: 'Context' object has no attribute 'send'", Traceback: "Traceback (most recent call last):  File "C:\Users\HOME\AppData\Local\Programs\Python\Python38-32\lib\site-packages\lightbulb\command_handler.py", line 852, in process_commands_for_event    await self._invoke_command(command, context, positional_args, keyword_arg)  File "C:\Users\HOME\AppData\Local\Programs\Python\Python38-32\lib\site-packages\lightbulb\command_handler.py", line 788, in _invoke_command    await command.invoke(context)  File "C:\Users\HOME\AppData\Local\Programs\Python\Python38-32\lib\site-packages\lightbulb\commands.py", line 88, in invoke    return await self._callback(instance, context, *new_args, **kwargs)  File "F:\Ahnaf's Folder\Shikamaru Bot\shikamaru\plugins\superuser.py", line 52, in code    await ctx.send(stdout)lightbulb.errors.CommandInvocationError: AttributeError: 'Context' object has no attribute 'send'"
2020-09-28 16:45:05 [Command Error] User: "Ahnaf#4346", Message: "sh!info", Error: "info", Traceback: "Traceback (most recent call last):  File "C:\Users\HOME\AppData\Local\Programs\Python\Python38-32\lib\site-packages\lightbulb\command_handler.py", line 813, in process_commands_for_event    command = self._validate_command_exists(invoked_with)  File "C:\Users\HOME\AppData\Local\Programs\Python\Python38-32\lib\site-packages\lightbulb\command_handler.py", line 730, in _validate_command_exists    raise errors.CommandNotFound(invoked_with)lightbulb.errors.CommandNotFound: info"
2020-09-28 16:55:23 [Command Error] User: "thomm.o#8637", Message: "sh!ping", Error: "ForbiddenError: Forbidden 403: 'Missing Permissions' for https://discord.com/api/v6/channels/727982024660615198/messages", Traceback: "Traceback (most recent call last):  File "C:\Users\HOME\AppData\Local\Programs\Python\Python38-32\lib\site-packages\lightbulb\command_handler.py", line 852, in process_commands_for_event    await self._invoke_command(command, context, positional_args, keyword_arg)  File "C:\Users\HOME\AppData\Local\Programs\Python\Python38-32\lib\site-packages\lightbulb\command_handler.py", line 788, in _invoke_command    await command.invoke(context)  File "C:\Users\HOME\AppData\Local\Programs\Python\Python38-32\lib\site-packages\lightbulb\commands.py", line 88, in invoke    return await self._callback(instance, context, *new_args, **kwargs)  File "F:\Ahnaf's Folder\Shikamaru Bot\shikamaru\plugins\info.py", line 26, in ping    msg = await ctx.reply("Pinging...")  File "C:\Users\HOME\AppData\Local\Programs\Python\Python38-32\lib\site-packages\lightbulb\context.py", line 193, in reply    return await self.message.reply(*args, **kwargs)  File "C:\Users\HOME\AppData\Local\Programs\Python\Python38-32\lib\site-packages\hikari\messages.py", line 649, in reply    return await self.app.rest.create_message(  File "C:\Users\HOME\AppData\Local\Programs\Python\Python38-32\lib\site-packages\hikari\impl\rest.py", line 1053, in create_message    raw_response = await self._request(route, json=body)  File "C:\Users\HOME\AppData\Local\Programs\Python\Python38-32\lib\site-packages\hikari\impl\rest.py", line 600, in _request    await self._handle_error_response(response)  File "C:\Users\HOME\AppData\Local\Programs\Python\Python38-32\lib\site-packages\hikari\impl\rest.py", line 621, in _handle_error_response    raise await net.generate_error_response(response)lightbulb.errors.CommandInvocationError: ForbiddenError: Forbidden 403: 'Missing Permissions' for https://discord.com/api/v6/channels/727982024660615198/messages"
2020-09-28 20:56:23 [Command Error] User: "Ahnaf#4346", Message: "sh!ping", Error: "ping", Traceback: "Traceback (most recent call last):  File "C:\Users\HOME\AppData\Local\Programs\Python\Python38-32\lib\site-packages\lightbulb\command_handler.py", line 813, in process_commands_for_event    command = self._validate_command_exists(invoked_with)  File "C:\Users\HOME\AppData\Local\Programs\Python\Python38-32\lib\site-packages\lightbulb\command_handler.py", line 730, in _validate_command_exists    raise errors.CommandNotFound(invoked_with)lightbulb.errors.CommandNotFound: ping"
2020-09-28 20:57:43 [Command Error] User: "4 times 1 is even less than 0#3870", Message: "sh!ping", Error: "ping", Traceback: "Traceback (most recent call last):  File "C:\Users\HOME\AppData\Local\Programs\Python\Python38-32\lib\site-packages\lightbulb\command_handler.py", line 813, in process_commands_for_event    command = self._validate_command_exists(invoked_with)  File "C:\Users\HOME\AppData\Local\Programs\Python\Python38-32\lib\site-packages\lightbulb\command_handler.py", line 730, in _validate_command_exists    raise errors.CommandNotFound(invoked_with)lightbulb.errors.CommandNotFound: ping"
2020-09-28 21:05:14 [Command Error] User: "Ahnaf#4346", Message: "sh!help", Error: "TypeError: set_thumbnail() got some positional-only arguments passed as keyword arguments: 'image'", Traceback: "Traceback (most recent call last):  File "C:\Users\HOME\AppData\Local\Programs\Python\Python38-32\lib\site-packages\lightbulb\command_handler.py", line 852, in process_commands_for_event    await self._invoke_command(command, context, positional_args, keyword_arg)  File "C:\Users\HOME\AppData\Local\Programs\Python\Python38-32\lib\site-packages\lightbulb\command_handler.py", line 788, in _invoke_command    await command.invoke(context)  File "C:\Users\HOME\AppData\Local\Programs\Python\Python38-32\lib\site-packages\lightbulb\commands.py", line 495, in invoke    return await self._callback(context, *new_args, **kwargs)  File "C:\Users\HOME\AppData\Local\Programs\Python\Python38-32\lib\site-packages\lightbulb\help.py", line 124, in _help_cmd    await ctx.bot.help_command.resolve_help_obj(ctx, obj)  File "C:\Users\HOME\AppData\Local\Programs\Python\Python38-32\lib\site-packages\lightbulb\help.py", line 175, in resolve_help_obj    await self.send_help_overview(context)  File "F:\Ahnaf's Folder\Shikamaru Bot\shikamaru\plugins\help.py", line 19, in send_help_overview    em.set_thumbnail(image=self.bot.me.avatar_url)lightbulb.errors.CommandInvocationError: TypeError: set_thumbnail() got some positional-only arguments passed as keyword arguments: 'image'"
2020-09-28 21:05:59 [Command Error] User: "Ahnaf#4346", Message: "sh!help", Error: "AttributeError: 'Bot' object has no attribute 'get_groups'", Traceback: "Traceback (most recent call last):  File "C:\Users\HOME\AppData\Local\Programs\Python\Python38-32\lib\site-packages\lightbulb\command_handler.py", line 852, in process_commands_for_event    await self._invoke_command(command, context, positional_args, keyword_arg)  File "C:\Users\HOME\AppData\Local\Programs\Python\Python38-32\lib\site-packages\lightbulb\command_handler.py", line 788, in _invoke_command    await command.invoke(context)  File "C:\Users\HOME\AppData\Local\Programs\Python\Python38-32\lib\site-packages\lightbulb\commands.py", line 495, in invoke    return await self._callback(context, *new_args, **kwargs)  File "C:\Users\HOME\AppData\Local\Programs\Python\Python38-32\lib\site-packages\lightbulb\help.py", line 124, in _help_cmd    await ctx.bot.help_command.resolve_help_obj(ctx, obj)  File "C:\Users\HOME\AppData\Local\Programs\Python\Python38-32\lib\site-packages\lightbulb\help.py", line 175, in resolve_help_obj    await self.send_help_overview(context)  File "F:\Ahnaf's Folder\Shikamaru Bot\shikamaru\plugins\help.py", line 21, in send_help_overview    print(self.bot.get_groups)lightbulb.errors.CommandInvocationError: AttributeError: 'Bot' object has no attribute 'get_groups'"
2020-09-28 21:06:38 [Command Error] User: "Ahnaf#4346", Message: "sh!help", Error: "AttributeError: 'BoundCommand' object has no attribute 'group'", Traceback: "Traceback (most recent call last):  File "C:\Users\HOME\AppData\Local\Programs\Python\Python38-32\lib\site-packages\lightbulb\command_handler.py", line 852, in process_commands_for_event    await self._invoke_command(command, context, positional_args, keyword_arg)  File "C:\Users\HOME\AppData\Local\Programs\Python\Python38-32\lib\site-packages\lightbulb\command_handler.py", line 788, in _invoke_command    await command.invoke(context)  File "C:\Users\HOME\AppData\Local\Programs\Python\Python38-32\lib\site-packages\lightbulb\commands.py", line 495, in invoke    return await self._callback(context, *new_args, **kwargs)  File "C:\Users\HOME\AppData\Local\Programs\Python\Python38-32\lib\site-packages\lightbulb\help.py", line 124, in _help_cmd    await ctx.bot.help_command.resolve_help_obj(ctx, obj)  File "C:\Users\HOME\AppData\Local\Programs\Python\Python38-32\lib\site-packages\lightbulb\help.py", line 175, in resolve_help_obj    await self.send_help_overview(context)  File "F:\Ahnaf's Folder\Shikamaru Bot\shikamaru\plugins\help.py", line 22, in send_help_overview    print(i.group)lightbulb.errors.CommandInvocationError: AttributeError: 'BoundCommand' object has no attribute 'group'"
2020-09-28 21:11:31 [Command Error] User: "Ahnaf#4346", Message: "sh!help", Error: "TypeError: reply() got an unexpected keyword argument 'em'", Traceback: "Traceback (most recent call last):  File "C:\Users\HOME\AppData\Local\Programs\Python\Python38-32\lib\site-packages\lightbulb\command_handler.py", line 852, in process_commands_for_event    await self._invoke_command(command, context, positional_args, keyword_arg)  File "C:\Users\HOME\AppData\Local\Programs\Python\Python38-32\lib\site-packages\lightbulb\command_handler.py", line 788, in _invoke_command    await command.invoke(context)  File "C:\Users\HOME\AppData\Local\Programs\Python\Python38-32\lib\site-packages\lightbulb\commands.py", line 495, in invoke    return await self._callback(context, *new_args, **kwargs)  File "C:\Users\HOME\AppData\Local\Programs\Python\Python38-32\lib\site-packages\lightbulb\help.py", line 124, in _help_cmd    await ctx.bot.help_command.resolve_help_obj(ctx, obj)  File "C:\Users\HOME\AppData\Local\Programs\Python\Python38-32\lib\site-packages\lightbulb\help.py", line 175, in resolve_help_obj    await self.send_help_overview(context)  File "F:\Ahnaf's Folder\Shikamaru Bot\shikamaru\plugins\help.py", line 22, in send_help_overview    await ctx.reply(em=em)  File "C:\Users\HOME\AppData\Local\Programs\Python\Python38-32\lib\site-packages\lightbulb\context.py", line 193, in reply    return await self.message.reply(*args, **kwargs)lightbulb.errors.CommandInvocationError: TypeError: reply() got an unexpected keyword argument 'em'"
2020-09-28 21:14:12 [Command Error] User: "Ahnaf#4346", Message: "sh!help", Error: "AttributeError: 'str' object has no attribute 'commands'", Traceback: "Traceback (most recent call last):  File "C:\Users\HOME\AppData\Local\Programs\Python\Python38-32\lib\site-packages\lightbulb\command_handler.py", line 852, in process_commands_for_event    await self._invoke_command(command, context, positional_args, keyword_arg)  File "C:\Users\HOME\AppData\Local\Programs\Python\Python38-32\lib\site-packages\lightbulb\command_handler.py", line 788, in _invoke_command    await command.invoke(context)  File "C:\Users\HOME\AppData\Local\Programs\Python\Python38-32\lib\site-packages\lightbulb\commands.py", line 495, in invoke    return await self._callback(context, *new_args, **kwargs)  File "C:\Users\HOME\AppData\Local\Programs\Python\Python38-32\lib\site-packages\lightbulb\help.py", line 124, in _help_cmd    await ctx.bot.help_command.resolve_help_obj(ctx, obj)  File "C:\Users\HOME\AppData\Local\Programs\Python\Python38-32\lib\site-packages\lightbulb\help.py", line 175, in resolve_help_obj    await self.send_help_overview(context)  File "F:\Ahnaf's Folder\Shikamaru Bot\shikamaru\plugins\help.py", line 21, in send_help_overview    em.add_field(name=str(plugin), value=f"{f'`cmd.name`, ' for cmd in plugin.commands}")lightbulb.errors.CommandInvocationError: AttributeError: 'str' object has no attribute 'commands'"
2020-09-28 21:19:18 [Command Error] User: "Ahnaf#4346", Message: "sh!help", Error: "TypeError: in embed.fields[0].value - cannot have empty string", Traceback: "Traceback (most recent call last):  File "C:\Users\HOME\AppData\Local\Programs\Python\Python38-32\lib\site-packages\lightbulb\command_handler.py", line 852, in process_commands_for_event    await self._invoke_command(command, context, positional_args, keyword_arg)  File "C:\Users\HOME\AppData\Local\Programs\Python\Python38-32\lib\site-packages\lightbulb\command_handler.py", line 788, in _invoke_command    await command.invoke(context)  File "C:\Users\HOME\AppData\Local\Programs\Python\Python38-32\lib\site-packages\lightbulb\commands.py", line 495, in invoke    return await self._callback(context, *new_args, **kwargs)  File "C:\Users\HOME\AppData\Local\Programs\Python\Python38-32\lib\site-packages\lightbulb\help.py", line 124, in _help_cmd    await ctx.bot.help_command.resolve_help_obj(ctx, obj)  File "C:\Users\HOME\AppData\Local\Programs\Python\Python38-32\lib\site-packages\lightbulb\help.py", line 175, in resolve_help_obj    await self.send_help_overview(context)  File "F:\Ahnaf's Folder\Shikamaru Bot\shikamaru\plugins\help.py", line 24, in send_help_overview    await ctx.reply(embed=em)  File "C:\Users\HOME\AppData\Local\Programs\Python\Python38-32\lib\site-packages\lightbulb\context.py", line 193, in reply    return await self.message.reply(*args, **kwargs)  File "C:\Users\HOME\AppData\Local\Programs\Python\Python38-32\lib\site-packages\hikari\messages.py", line 649, in reply    return await self.app.rest.create_message(  File "C:\Users\HOME\AppData\Local\Programs\Python\Python38-32\lib\site-packages\hikari\impl\rest.py", line 1034, in create_message    embed_payload, embed_attachments = self._entity_factory.serialize_embed(embed)  File "C:\Users\HOME\AppData\Local\Programs\Python\Python38-32\lib\site-packages\hikari\impl\entity_factory.py", line 888, in serialize_embed    raise TypeError(f"in embed.fields[{i}].value - cannot have empty string")lightbulb.errors.CommandInvocationError: TypeError: in embed.fields[0].value - cannot have empty string"
2020-09-28 21:27:43 [Command Error] User: "Ahnaf#4346", Message: "sh!help", Error: "TypeError: in embed.fields[0].value - cannot have empty string", Traceback: "Traceback (most recent call last):  File "C:\Users\HOME\AppData\Local\Programs\Python\Python38-32\lib\site-packages\lightbulb\command_handler.py", line 852, in process_commands_for_event    await self._invoke_command(command, context, positional_args, keyword_arg)  File "C:\Users\HOME\AppData\Local\Programs\Python\Python38-32\lib\site-packages\lightbulb\command_handler.py", line 788, in _invoke_command    await command.invoke(context)  File "C:\Users\HOME\AppData\Local\Programs\Python\Python38-32\lib\site-packages\lightbulb\commands.py", line 495, in invoke    return await self._callback(context, *new_args, **kwargs)  File "C:\Users\HOME\AppData\Local\Programs\Python\Python38-32\lib\site-packages\lightbulb\help.py", line 124, in _help_cmd    await ctx.bot.help_command.resolve_help_obj(ctx, obj)  File "C:\Users\HOME\AppData\Local\Programs\Python\Python38-32\lib\site-packages\lightbulb\help.py", line 175, in resolve_help_obj    await self.send_help_overview(context)  File "F:\Ahnaf's Folder\Shikamaru Bot\shikamaru\plugins\help.py", line 30, in send_help_overview    await ctx.reply(embed=em)  File "C:\Users\HOME\AppData\Local\Programs\Python\Python38-32\lib\site-packages\lightbulb\context.py", line 193, in reply    return await self.message.reply(*args, **kwargs)  File "C:\Users\HOME\AppData\Local\Programs\Python\Python38-32\lib\site-packages\hikari\messages.py", line 649, in reply    return await self.app.rest.create_message(  File "C:\Users\HOME\AppData\Local\Programs\Python\Python38-32\lib\site-packages\hikari\impl\rest.py", line 1034, in create_message    embed_payload, embed_attachments = self._entity_factory.serialize_embed(embed)  File "C:\Users\HOME\AppData\Local\Programs\Python\Python38-32\lib\site-packages\hikari\impl\entity_factory.py", line 888, in serialize_embed    raise TypeError(f"in embed.fields[{i}].value - cannot have empty string")lightbulb.errors.CommandInvocationError: TypeError: in embed.fields[0].value - cannot have empty string"
2020-09-28 21:45:11 [Command Error] User: "Ahnaf#4346", Message: "sh!help", Error: "TypeError: in embed.fields[0].value - cannot have empty string", Traceback: "Traceback (most recent call last):  File "C:\Users\HOME\AppData\Local\Programs\Python\Python38-32\lib\site-packages\lightbulb\command_handler.py", line 852, in process_commands_for_event    await self._invoke_command(command, context, positional_args, keyword_arg)  File "C:\Users\HOME\AppData\Local\Programs\Python\Python38-32\lib\site-packages\lightbulb\command_handler.py", line 788, in _invoke_command    await command.invoke(context)  File "C:\Users\HOME\AppData\Local\Programs\Python\Python38-32\lib\site-packages\lightbulb\commands.py", line 495, in invoke    return await self._callback(context, *new_args, **kwargs)  File "C:\Users\HOME\AppData\Local\Programs\Python\Python38-32\lib\site-packages\lightbulb\help.py", line 124, in _help_cmd    await ctx.bot.help_command.resolve_help_obj(ctx, obj)  File "C:\Users\HOME\AppData\Local\Programs\Python\Python38-32\lib\site-packages\lightbulb\help.py", line 175, in resolve_help_obj    await self.send_help_overview(context)  File "F:\Ahnaf's Folder\Shikamaru Bot\shikamaru\plugins\help.py", line 30, in send_help_overview    await ctx.reply(embed=em)  File "C:\Users\HOME\AppData\Local\Programs\Python\Python38-32\lib\site-packages\lightbulb\context.py", line 193, in reply    return await self.message.reply(*args, **kwargs)  File "C:\Users\HOME\AppData\Local\Programs\Python\Python38-32\lib\site-packages\hikari\messages.py", line 649, in reply    return await self.app.rest.create_message(  File "C:\Users\HOME\AppData\Local\Programs\Python\Python38-32\lib\site-packages\hikari\impl\rest.py", line 1034, in create_message    embed_payload, embed_attachments = self._entity_factory.serialize_embed(embed)  File "C:\Users\HOME\AppData\Local\Programs\Python\Python38-32\lib\site-packages\hikari\impl\entity_factory.py", line 888, in serialize_embed    raise TypeError(f"in embed.fields[{i}].value - cannot have empty string")lightbulb.errors.CommandInvocationError: TypeError: in embed.fields[0].value - cannot have empty string"
2020-09-28 21:45:47 [Command Error] User: "Ahnaf#4346", Message: "sh!help", Error: "TypeError: in embed.fields[0].value - cannot have empty string", Traceback: "Traceback (most recent call last):  File "C:\Users\HOME\AppData\Local\Programs\Python\Python38-32\lib\site-packages\lightbulb\command_handler.py", line 852, in process_commands_for_event    await self._invoke_command(command, context, positional_args, keyword_arg)  File "C:\Users\HOME\AppData\Local\Programs\Python\Python38-32\lib\site-packages\lightbulb\command_handler.py", line 788, in _invoke_command    await command.invoke(context)  File "C:\Users\HOME\AppData\Local\Programs\Python\Python38-32\lib\site-packages\lightbulb\commands.py", line 495, in invoke    return await self._callback(context, *new_args, **kwargs)  File "C:\Users\HOME\AppData\Local\Programs\Python\Python38-32\lib\site-packages\lightbulb\help.py", line 124, in _help_cmd    await ctx.bot.help_command.resolve_help_obj(ctx, obj)  File "C:\Users\HOME\AppData\Local\Programs\Python\Python38-32\lib\site-packages\lightbulb\help.py", line 175, in resolve_help_obj    await self.send_help_overview(context)  File "F:\Ahnaf's Folder\Shikamaru Bot\shikamaru\plugins\help.py", line 30, in send_help_overview    await ctx.reply(embed=em)  File "C:\Users\HOME\AppData\Local\Programs\Python\Python38-32\lib\site-packages\lightbulb\context.py", line 193, in reply    return await self.message.reply(*args, **kwargs)  File "C:\Users\HOME\AppData\Local\Programs\Python\Python38-32\lib\site-packages\hikari\messages.py", line 649, in reply    return await self.app.rest.create_message(  File "C:\Users\HOME\AppData\Local\Programs\Python\Python38-32\lib\site-packages\hikari\impl\rest.py", line 1034, in create_message    embed_payload, embed_attachments = self._entity_factory.serialize_embed(embed)  File "C:\Users\HOME\AppData\Local\Programs\Python\Python38-32\lib\site-packages\hikari\impl\entity_factory.py", line 888, in serialize_embed    raise TypeError(f"in embed.fields[{i}].value - cannot have empty string")lightbulb.errors.CommandInvocationError: TypeError: in embed.fields[0].value - cannot have empty string"
2020-09-28 21:46:52 [Command Error] User: "Ahnaf#4346", Message: "sh!help", Error: "TypeError: in embed.fields[0].value - cannot have empty string", Traceback: "Traceback (most recent call last):  File "C:\Users\HOME\AppData\Local\Programs\Python\Python38-32\lib\site-packages\lightbulb\command_handler.py", line 852, in process_commands_for_event    await self._invoke_command(command, context, positional_args, keyword_arg)  File "C:\Users\HOME\AppData\Local\Programs\Python\Python38-32\lib\site-packages\lightbulb\command_handler.py", line 788, in _invoke_command    await command.invoke(context)  File "C:\Users\HOME\AppData\Local\Programs\Python\Python38-32\lib\site-packages\lightbulb\commands.py", line 495, in invoke    return await self._callback(context, *new_args, **kwargs)  File "C:\Users\HOME\AppData\Local\Programs\Python\Python38-32\lib\site-packages\lightbulb\help.py", line 124, in _help_cmd    await ctx.bot.help_command.resolve_help_obj(ctx, obj)  File "C:\Users\HOME\AppData\Local\Programs\Python\Python38-32\lib\site-packages\lightbulb\help.py", line 175, in resolve_help_obj    await self.send_help_overview(context)  File "F:\Ahnaf's Folder\Shikamaru Bot\shikamaru\plugins\help.py", line 30, in send_help_overview    await ctx.reply(embed=em)  File "C:\Users\HOME\AppData\Local\Programs\Python\Python38-32\lib\site-packages\lightbulb\context.py", line 193, in reply    return await self.message.reply(*args, **kwargs)  File "C:\Users\HOME\AppData\Local\Programs\Python\Python38-32\lib\site-packages\hikari\messages.py", line 649, in reply    return await self.app.rest.create_message(  File "C:\Users\HOME\AppData\Local\Programs\Python\Python38-32\lib\site-packages\hikari\impl\rest.py", line 1034, in create_message    embed_payload, embed_attachments = self._entity_factory.serialize_embed(embed)  File "C:\Users\HOME\AppData\Local\Programs\Python\Python38-32\lib\site-packages\hikari\impl\entity_factory.py", line 888, in serialize_embed    raise TypeError(f"in embed.fields[{i}].value - cannot have empty string")lightbulb.errors.CommandInvocationError: TypeError: in embed.fields[0].value - cannot have empty string"
2020-09-28 21:47:54 [Command Error] User: "Ahnaf#4346", Message: "sh!help", Error: "TypeError: in embed.fields[0].value - cannot have empty string", Traceback: "Traceback (most recent call last):  File "C:\Users\HOME\AppData\Local\Programs\Python\Python38-32\lib\site-packages\lightbulb\command_handler.py", line 852, in process_commands_for_event    await self._invoke_command(command, context, positional_args, keyword_arg)  File "C:\Users\HOME\AppData\Local\Programs\Python\Python38-32\lib\site-packages\lightbulb\command_handler.py", line 788, in _invoke_command    await command.invoke(context)  File "C:\Users\HOME\AppData\Local\Programs\Python\Python38-32\lib\site-packages\lightbulb\commands.py", line 495, in invoke    return await self._callback(context, *new_args, **kwargs)  File "C:\Users\HOME\AppData\Local\Programs\Python\Python38-32\lib\site-packages\lightbulb\help.py", line 124, in _help_cmd    await ctx.bot.help_command.resolve_help_obj(ctx, obj)  File "C:\Users\HOME\AppData\Local\Programs\Python\Python38-32\lib\site-packages\lightbulb\help.py", line 175, in resolve_help_obj    await self.send_help_overview(context)  File "F:\Ahnaf's Folder\Shikamaru Bot\shikamaru\plugins\help.py", line 30, in send_help_overview    await ctx.reply(embed=em)  File "C:\Users\HOME\AppData\Local\Programs\Python\Python38-32\lib\site-packages\lightbulb\context.py", line 193, in reply    return await self.message.reply(*args, **kwargs)  File "C:\Users\HOME\AppData\Local\Programs\Python\Python38-32\lib\site-packages\hikari\messages.py", line 649, in reply    return await self.app.rest.create_message(  File "C:\Users\HOME\AppData\Local\Programs\Python\Python38-32\lib\site-packages\hikari\impl\rest.py", line 1034, in create_message    embed_payload, embed_attachments = self._entity_factory.serialize_embed(embed)  File "C:\Users\HOME\AppData\Local\Programs\Python\Python38-32\lib\site-packages\hikari\impl\entity_factory.py", line 888, in serialize_embed    raise TypeError(f"in embed.fields[{i}].value - cannot have empty string")lightbulb.errors.CommandInvocationError: TypeError: in embed.fields[0].value - cannot have empty string"
2020-09-28 21:48:56 [Command Error] User: "Ahnaf#4346", Message: "sh!help", Error: "TypeError: in embed.fields[0].value - cannot have empty string", Traceback: "Traceback (most recent call last):  File "C:\Users\HOME\AppData\Local\Programs\Python\Python38-32\lib\site-packages\lightbulb\command_handler.py", line 852, in process_commands_for_event    await self._invoke_command(command, context, positional_args, keyword_arg)  File "C:\Users\HOME\AppData\Local\Programs\Python\Python38-32\lib\site-packages\lightbulb\command_handler.py", line 788, in _invoke_command    await command.invoke(context)  File "C:\Users\HOME\AppData\Local\Programs\Python\Python38-32\lib\site-packages\lightbulb\commands.py", line 495, in invoke    return await self._callback(context, *new_args, **kwargs)  File "C:\Users\HOME\AppData\Local\Programs\Python\Python38-32\lib\site-packages\lightbulb\help.py", line 124, in _help_cmd    await ctx.bot.help_command.resolve_help_obj(ctx, obj)  File "C:\Users\HOME\AppData\Local\Programs\Python\Python38-32\lib\site-packages\lightbulb\help.py", line 175, in resolve_help_obj    await self.send_help_overview(context)  File "F:\Ahnaf's Folder\Shikamaru Bot\shikamaru\plugins\help.py", line 31, in send_help_overview    await ctx.reply(embed=em)  File "C:\Users\HOME\AppData\Local\Programs\Python\Python38-32\lib\site-packages\lightbulb\context.py", line 193, in reply    return await self.message.reply(*args, **kwargs)  File "C:\Users\HOME\AppData\Local\Programs\Python\Python38-32\lib\site-packages\hikari\messages.py", line 649, in reply    return await self.app.rest.create_message(  File "C:\Users\HOME\AppData\Local\Programs\Python\Python38-32\lib\site-packages\hikari\impl\rest.py", line 1034, in create_message    embed_payload, embed_attachments = self._entity_factory.serialize_embed(embed)  File "C:\Users\HOME\AppData\Local\Programs\Python\Python38-32\lib\site-packages\hikari\impl\entity_factory.py", line 888, in serialize_embed    raise TypeError(f"in embed.fields[{i}].value - cannot have empty string")lightbulb.errors.CommandInvocationError: TypeError: in embed.fields[0].value - cannot have empty string"
2020-09-28 21:51:20 [Command Error] User: "Ahnaf#4346", Message: "sh!help", Error: "TypeError: in embed.fields[1].value - cannot have empty string", Traceback: "Traceback (most recent call last):  File "C:\Users\HOME\AppData\Local\Programs\Python\Python38-32\lib\site-packages\lightbulb\command_handler.py", line 852, in process_commands_for_event    await self._invoke_command(command, context, positional_args, keyword_arg)  File "C:\Users\HOME\AppData\Local\Programs\Python\Python38-32\lib\site-packages\lightbulb\command_handler.py", line 788, in _invoke_command    await command.invoke(context)  File "C:\Users\HOME\AppData\Local\Programs\Python\Python38-32\lib\site-packages\lightbulb\commands.py", line 495, in invoke    return await self._callback(context, *new_args, **kwargs)  File "C:\Users\HOME\AppData\Local\Programs\Python\Python38-32\lib\site-packages\lightbulb\help.py", line 124, in _help_cmd    await ctx.bot.help_command.resolve_help_obj(ctx, obj)  File "C:\Users\HOME\AppData\Local\Programs\Python\Python38-32\lib\site-packages\lightbulb\help.py", line 175, in resolve_help_obj    await self.send_help_overview(context)  File "F:\Ahnaf's Folder\Shikamaru Bot\shikamaru\plugins\help.py", line 33, in send_help_overview    await ctx.reply(embed=em)  File "C:\Users\HOME\AppData\Local\Programs\Python\Python38-32\lib\site-packages\lightbulb\context.py", line 193, in reply    return await self.message.reply(*args, **kwargs)  File "C:\Users\HOME\AppData\Local\Programs\Python\Python38-32\lib\site-packages\hikari\messages.py", line 649, in reply    return await self.app.rest.create_message(  File "C:\Users\HOME\AppData\Local\Programs\Python\Python38-32\lib\site-packages\hikari\impl\rest.py", line 1034, in create_message    embed_payload, embed_attachments = self._entity_factory.serialize_embed(embed)  File "C:\Users\HOME\AppData\Local\Programs\Python\Python38-32\lib\site-packages\hikari\impl\entity_factory.py", line 888, in serialize_embed    raise TypeError(f"in embed.fields[{i}].value - cannot have empty string")lightbulb.errors.CommandInvocationError: TypeError: in embed.fields[1].value - cannot have empty string"
2020-09-28 21:51:57 [Command Error] User: "Ahnaf#4346", Message: "sh!help", Error: "TypeError: in embed.fields[1].value - cannot have empty string", Traceback: "Traceback (most recent call last):  File "C:\Users\HOME\AppData\Local\Programs\Python\Python38-32\lib\site-packages\lightbulb\command_handler.py", line 852, in process_commands_for_event    await self._invoke_command(command, context, positional_args, keyword_arg)  File "C:\Users\HOME\AppData\Local\Programs\Python\Python38-32\lib\site-packages\lightbulb\command_handler.py", line 788, in _invoke_command    await command.invoke(context)  File "C:\Users\HOME\AppData\Local\Programs\Python\Python38-32\lib\site-packages\lightbulb\commands.py", line 495, in invoke    return await self._callback(context, *new_args, **kwargs)  File "C:\Users\HOME\AppData\Local\Programs\Python\Python38-32\lib\site-packages\lightbulb\help.py", line 124, in _help_cmd    await ctx.bot.help_command.resolve_help_obj(ctx, obj)  File "C:\Users\HOME\AppData\Local\Programs\Python\Python38-32\lib\site-packages\lightbulb\help.py", line 175, in resolve_help_obj    await self.send_help_overview(context)  File "F:\Ahnaf's Folder\Shikamaru Bot\shikamaru\plugins\help.py", line 33, in send_help_overview    await ctx.reply(embed=em)  File "C:\Users\HOME\AppData\Local\Programs\Python\Python38-32\lib\site-packages\lightbulb\context.py", line 193, in reply    return await self.message.reply(*args, **kwargs)  File "C:\Users\HOME\AppData\Local\Programs\Python\Python38-32\lib\site-packages\hikari\messages.py", line 649, in reply    return await self.app.rest.create_message(  File "C:\Users\HOME\AppData\Local\Programs\Python\Python38-32\lib\site-packages\hikari\impl\rest.py", line 1034, in create_message    embed_payload, embed_attachments = self._entity_factory.serialize_embed(embed)  File "C:\Users\HOME\AppData\Local\Programs\Python\Python38-32\lib\site-packages\hikari\impl\entity_factory.py", line 888, in serialize_embed    raise TypeError(f"in embed.fields[{i}].value - cannot have empty string")lightbulb.errors.CommandInvocationError: TypeError: in embed.fields[1].value - cannot have empty string"
2020-09-28 21:53:56 [Command Error] User: "Ahnaf#4346", Message: "sh!help", Error: "TypeError: in embed.fields[1].value - cannot have empty string", Traceback: "Traceback (most recent call last):  File "C:\Users\HOME\AppData\Local\Programs\Python\Python38-32\lib\site-packages\lightbulb\command_handler.py", line 852, in process_commands_for_event    await self._invoke_command(command, context, positional_args, keyword_arg)  File "C:\Users\HOME\AppData\Local\Programs\Python\Python38-32\lib\site-packages\lightbulb\command_handler.py", line 788, in _invoke_command    await command.invoke(context)  File "C:\Users\HOME\AppData\Local\Programs\Python\Python38-32\lib\site-packages\lightbulb\commands.py", line 495, in invoke    return await self._callback(context, *new_args, **kwargs)  File "C:\Users\HOME\AppData\Local\Programs\Python\Python38-32\lib\site-packages\lightbulb\help.py", line 124, in _help_cmd    await ctx.bot.help_command.resolve_help_obj(ctx, obj)  File "C:\Users\HOME\AppData\Local\Programs\Python\Python38-32\lib\site-packages\lightbulb\help.py", line 175, in resolve_help_obj    await self.send_help_overview(context)  File "F:\Ahnaf's Folder\Shikamaru Bot\shikamaru\plugins\help.py", line 33, in send_help_overview    await ctx.reply(embed=em)  File "C:\Users\HOME\AppData\Local\Programs\Python\Python38-32\lib\site-packages\lightbulb\context.py", line 193, in reply    return await self.message.reply(*args, **kwargs)  File "C:\Users\HOME\AppData\Local\Programs\Python\Python38-32\lib\site-packages\hikari\messages.py", line 649, in reply    return await self.app.rest.create_message(  File "C:\Users\HOME\AppData\Local\Programs\Python\Python38-32\lib\site-packages\hikari\impl\rest.py", line 1034, in create_message    embed_payload, embed_attachments = self._entity_factory.serialize_embed(embed)  File "C:\Users\HOME\AppData\Local\Programs\Python\Python38-32\lib\site-packages\hikari\impl\entity_factory.py", line 888, in serialize_embed    raise TypeError(f"in embed.fields[{i}].value - cannot have empty string")lightbulb.errors.CommandInvocationError: TypeError: in embed.fields[1].value - cannot have empty string"
2020-09-28 21:55:26 [Command Error] User: "Ahnaf#4346", Message: "sh!help", Error: "BadRequestError: Bad Request 400: 'Cannot send an empty message' for https://discord.com/api/v6/channels/715942542864154728/messages", Traceback: "Traceback (most recent call last):  File "C:\Users\HOME\AppData\Local\Programs\Python\Python38-32\lib\site-packages\lightbulb\command_handler.py", line 852, in process_commands_for_event    await self._invoke_command(command, context, positional_args, keyword_arg)  File "C:\Users\HOME\AppData\Local\Programs\Python\Python38-32\lib\site-packages\lightbulb\command_handler.py", line 788, in _invoke_command    await command.invoke(context)  File "C:\Users\HOME\AppData\Local\Programs\Python\Python38-32\lib\site-packages\lightbulb\commands.py", line 495, in invoke    return await self._callback(context, *new_args, **kwargs)  File "C:\Users\HOME\AppData\Local\Programs\Python\Python38-32\lib\site-packages\lightbulb\help.py", line 124, in _help_cmd    await ctx.bot.help_command.resolve_help_obj(ctx, obj)  File "C:\Users\HOME\AppData\Local\Programs\Python\Python38-32\lib\site-packages\lightbulb\help.py", line 175, in resolve_help_obj    await self.send_help_overview(context)  File "F:\Ahnaf's Folder\Shikamaru Bot\shikamaru\plugins\help.py", line 30, in send_help_overview    await ctx.reply(string)  File "C:\Users\HOME\AppData\Local\Programs\Python\Python38-32\lib\site-packages\lightbulb\context.py", line 193, in reply    return await self.message.reply(*args, **kwargs)  File "C:\Users\HOME\AppData\Local\Programs\Python\Python38-32\lib\site-packages\hikari\messages.py", line 649, in reply    return await self.app.rest.create_message(  File "C:\Users\HOME\AppData\Local\Programs\Python\Python38-32\lib\site-packages\hikari\impl\rest.py", line 1053, in create_message    raw_response = await self._request(route, json=body)  File "C:\Users\HOME\AppData\Local\Programs\Python\Python38-32\lib\site-packages\hikari\impl\rest.py", line 600, in _request    await self._handle_error_response(response)  File "C:\Users\HOME\AppData\Local\Programs\Python\Python38-32\lib\site-packages\hikari\impl\rest.py", line 621, in _handle_error_response    raise await net.generate_error_response(response)lightbulb.errors.CommandInvocationError: BadRequestError: Bad Request 400: 'Cannot send an empty message' for https://discord.com/api/v6/channels/715942542864154728/messages"
2020-09-28 21:56:48 [Command Error] User: "Ahnaf#4346", Message: "sh!help", Error: "BadRequestError: Bad Request 400: 'Cannot send an empty message' for https://discord.com/api/v6/channels/715942542864154728/messages", Traceback: "Traceback (most recent call last):  File "C:\Users\HOME\AppData\Local\Programs\Python\Python38-32\lib\site-packages\lightbulb\command_handler.py", line 852, in process_commands_for_event    await self._invoke_command(command, context, positional_args, keyword_arg)  File "C:\Users\HOME\AppData\Local\Programs\Python\Python38-32\lib\site-packages\lightbulb\command_handler.py", line 788, in _invoke_command    await command.invoke(context)  File "C:\Users\HOME\AppData\Local\Programs\Python\Python38-32\lib\site-packages\lightbulb\commands.py", line 495, in invoke    return await self._callback(context, *new_args, **kwargs)  File "C:\Users\HOME\AppData\Local\Programs\Python\Python38-32\lib\site-packages\lightbulb\help.py", line 124, in _help_cmd    await ctx.bot.help_command.resolve_help_obj(ctx, obj)  File "C:\Users\HOME\AppData\Local\Programs\Python\Python38-32\lib\site-packages\lightbulb\help.py", line 175, in resolve_help_obj    await self.send_help_overview(context)  File "F:\Ahnaf's Folder\Shikamaru Bot\shikamaru\plugins\help.py", line 31, in send_help_overview    await ctx.reply(string)  File "C:\Users\HOME\AppData\Local\Programs\Python\Python38-32\lib\site-packages\lightbulb\context.py", line 193, in reply    return await self.message.reply(*args, **kwargs)  File "C:\Users\HOME\AppData\Local\Programs\Python\Python38-32\lib\site-packages\hikari\messages.py", line 649, in reply    return await self.app.rest.create_message(  File "C:\Users\HOME\AppData\Local\Programs\Python\Python38-32\lib\site-packages\hikari\impl\rest.py", line 1053, in create_message    raw_response = await self._request(route, json=body)  File "C:\Users\HOME\AppData\Local\Programs\Python\Python38-32\lib\site-packages\hikari\impl\rest.py", line 600, in _request    await self._handle_error_response(response)  File "C:\Users\HOME\AppData\Local\Programs\Python\Python38-32\lib\site-packages\hikari\impl\rest.py", line 621, in _handle_error_response    raise await net.generate_error_response(response)lightbulb.errors.CommandInvocationError: BadRequestError: Bad Request 400: 'Cannot send an empty message' for https://discord.com/api/v6/channels/715942542864154728/messages"
2020-09-28 22:14:56 [Command Error] User: "Ahnaf#4346", Message: "sh!help dasdsdasdsa", Error: "TypeError: reply() takes from 1 to 2 positional arguments but 3 were given", Traceback: "Traceback (most recent call last):  File "C:\Users\HOME\AppData\Local\Programs\Python\Python38-32\lib\site-packages\lightbulb\command_handler.py", line 852, in process_commands_for_event    await self._invoke_command(command, context, positional_args, keyword_arg)  File "C:\Users\HOME\AppData\Local\Programs\Python\Python38-32\lib\site-packages\lightbulb\command_handler.py", line 788, in _invoke_command    await command.invoke(context)  File "C:\Users\HOME\AppData\Local\Programs\Python\Python38-32\lib\site-packages\lightbulb\commands.py", line 495, in invoke    return await self._callback(context, *new_args, **kwargs)  File "C:\Users\HOME\AppData\Local\Programs\Python\Python38-32\lib\site-packages\lightbulb\help.py", line 124, in _help_cmd    await ctx.bot.help_command.resolve_help_obj(ctx, obj)  File "C:\Users\HOME\AppData\Local\Programs\Python\Python38-32\lib\site-packages\lightbulb\help.py", line 187, in resolve_help_obj    await self.object_not_found(context, obj[0])  File "F:\Ahnaf's Folder\Shikamaru Bot\shikamaru\plugins\help.py", line 14, in object_not_found    await ctx.reply("Command/Category not found for", name)  File "C:\Users\HOME\AppData\Local\Programs\Python\Python38-32\lib\site-packages\lightbulb\context.py", line 193, in reply    return await self.message.reply(*args, **kwargs)lightbulb.errors.CommandInvocationError: TypeError: reply() takes from 1 to 2 positional arguments but 3 were given"
2020-09-29 17:02:37 [Command Error] User: "Forbidden#0001", Message: "sh!t", Error: "t", Traceback: "Traceback (most recent call last):  File "/usr/local/lib/python3.8/site-packages/lightbulb/command_handler.py", line 813, in process_commands_for_event    command = self._validate_command_exists(invoked_with)  File "/usr/local/lib/python3.8/site-packages/lightbulb/command_handler.py", line 730, in _validate_command_exists    raise errors.CommandNotFound(invoked_with)lightbulb.errors.CommandNotFound: t"
2020-09-29 17:03:16 [Command Error] User: "Forbidden#0001", Message: "sh!cat", Error: "cat", Traceback: "Traceback (most recent call last):  File "/usr/local/lib/python3.8/site-packages/lightbulb/command_handler.py", line 813, in process_commands_for_event    command = self._validate_command_exists(invoked_with)  File "/usr/local/lib/python3.8/site-packages/lightbulb/command_handler.py", line 730, in _validate_command_exists    raise errors.CommandNotFound(invoked_with)lightbulb.errors.CommandNotFound: cat"
2020-09-29 17:03:28 [Command Error] User: "Forbidden#0001", Message: "sh!reddit", Error: "reddit", Traceback: "Traceback (most recent call last):  File "/usr/local/lib/python3.8/site-packages/lightbulb/command_handler.py", line 813, in process_commands_for_event    command = self._validate_command_exists(invoked_with)  File "/usr/local/lib/python3.8/site-packages/lightbulb/command_handler.py", line 730, in _validate_command_exists    raise errors.CommandNotFound(invoked_with)lightbulb.errors.CommandNotFound: reddit"
2020-09-29 17:06:31 [Command Error] User: "Hjacobs#9441", Message: "sh!pandas dataset", Error: "pandas", Traceback: "Traceback (most recent call last):  File "/usr/local/lib/python3.8/site-packages/lightbulb/command_handler.py", line 813, in process_commands_for_event    command = self._validate_command_exists(invoked_with)  File "/usr/local/lib/python3.8/site-packages/lightbulb/command_handler.py", line 730, in _validate_command_exists    raise errors.CommandNotFound(invoked_with)lightbulb.errors.CommandNotFound: pandas"
2020-09-29 17:20:16 [Command Error] User: "Hjacobs#9441", Message: "sh! print(“I hate dogs”)", Error: "", Traceback: "Traceback (most recent call last):  File "/usr/local/lib/python3.8/site-packages/lightbulb/command_handler.py", line 813, in process_commands_for_event    command = self._validate_command_exists(invoked_with)  File "/usr/local/lib/python3.8/site-packages/lightbulb/command_handler.py", line 730, in _validate_command_exists    raise errors.CommandNotFound(invoked_with)lightbulb.errors.CommandNotFound"
2020-09-29 17:27:40 [Command Error] User: "Ahnaf#4346", Message: "sh!help", Error: "AttributeError: 'dict' object has no attribute 'sort'", Traceback: "Traceback (most recent call last):  File "/usr/local/lib/python3.8/site-packages/lightbulb/command_handler.py", line 852, in process_commands_for_event    await self._invoke_command(command, context, positional_args, keyword_arg)  File "/usr/local/lib/python3.8/site-packages/lightbulb/command_handler.py", line 788, in _invoke_command    await command.invoke(context)  File "/usr/local/lib/python3.8/site-packages/lightbulb/commands.py", line 495, in invoke    return await self._callback(context, *new_args, **kwargs)  File "/usr/local/lib/python3.8/site-packages/lightbulb/help.py", line 124, in _help_cmd    await ctx.bot.help_command.resolve_help_obj(ctx, obj)  File "/usr/local/lib/python3.8/site-packages/lightbulb/help.py", line 175, in resolve_help_obj    await self.send_help_overview(context)  File "/home/ahnaf/Documents/shikamaru-bot/shikamaru/plugins/help.py", line 19, in send_help_overview    plugins = self.bot.plugins.sort()lightbulb.errors.CommandInvocationError: AttributeError: 'dict' object has no attribute 'sort'"
2020-09-29 17:28:48 [Command Error] User: "Ahnaf#4346", Message: "sh!help", Error: "TypeError: 'NoneType' object is not iterable", Traceback: "Traceback (most recent call last):  File "/usr/local/lib/python3.8/site-packages/lightbulb/command_handler.py", line 852, in process_commands_for_event    await self._invoke_command(command, context, positional_args, keyword_arg)  File "/usr/local/lib/python3.8/site-packages/lightbulb/command_handler.py", line 788, in _invoke_command    await command.invoke(context)  File "/usr/local/lib/python3.8/site-packages/lightbulb/commands.py", line 495, in invoke    return await self._callback(context, *new_args, **kwargs)  File "/usr/local/lib/python3.8/site-packages/lightbulb/help.py", line 124, in _help_cmd    await ctx.bot.help_command.resolve_help_obj(ctx, obj)  File "/usr/local/lib/python3.8/site-packages/lightbulb/help.py", line 175, in resolve_help_obj    await self.send_help_overview(context)  File "/home/ahnaf/Documents/shikamaru-bot/shikamaru/plugins/help.py", line 20, in send_help_overview    for plugin in plugins:lightbulb.errors.CommandInvocationError: TypeError: 'NoneType' object is not iterable"
2020-09-29 17:29:05 [Command Error] User: "Ahnaf#4346", Message: "sh!help", Error: "TypeError: 'NoneType' object is not iterable", Traceback: "Traceback (most recent call last):  File "/usr/local/lib/python3.8/site-packages/lightbulb/command_handler.py", line 852, in process_commands_for_event    await self._invoke_command(command, context, positional_args, keyword_arg)  File "/usr/local/lib/python3.8/site-packages/lightbulb/command_handler.py", line 788, in _invoke_command    await command.invoke(context)  File "/usr/local/lib/python3.8/site-packages/lightbulb/commands.py", line 495, in invoke    return await self._callback(context, *new_args, **kwargs)  File "/usr/local/lib/python3.8/site-packages/lightbulb/help.py", line 124, in _help_cmd    await ctx.bot.help_command.resolve_help_obj(ctx, obj)  File "/usr/local/lib/python3.8/site-packages/lightbulb/help.py", line 175, in resolve_help_obj    await self.send_help_overview(context)  File "/home/ahnaf/Documents/shikamaru-bot/shikamaru/plugins/help.py", line 20, in send_help_overview    for plugin in plugins:lightbulb.errors.CommandInvocationError: TypeError: 'NoneType' object is not iterable"
2020-09-29 17:29:27 [Command Error] User: "Ahnaf#4346", Message: "sh!help", Error: "TypeError: 'NoneType' object is not iterable", Traceback: "Traceback (most recent call last):  File "/usr/local/lib/python3.8/site-packages/lightbulb/command_handler.py", line 852, in process_commands_for_event    await self._invoke_command(command, context, positional_args, keyword_arg)  File "/usr/local/lib/python3.8/site-packages/lightbulb/command_handler.py", line 788, in _invoke_command    await command.invoke(context)  File "/usr/local/lib/python3.8/site-packages/lightbulb/commands.py", line 495, in invoke    return await self._callback(context, *new_args, **kwargs)  File "/usr/local/lib/python3.8/site-packages/lightbulb/help.py", line 124, in _help_cmd    await ctx.bot.help_command.resolve_help_obj(ctx, obj)  File "/usr/local/lib/python3.8/site-packages/lightbulb/help.py", line 175, in resolve_help_obj    await self.send_help_overview(context)  File "/home/ahnaf/Documents/shikamaru-bot/shikamaru/plugins/help.py", line 21, in send_help_overview    for plugin in plugins:lightbulb.errors.CommandInvocationError: TypeError: 'NoneType' object is not iterable"
2020-09-29 17:30:59 [Command Error] User: "Ahnaf#4346", Message: "sh!help", Error: "TypeError: 'NoneType' object is not iterable", Traceback: "Traceback (most recent call last):  File "/usr/local/lib/python3.8/site-packages/lightbulb/command_handler.py", line 852, in process_commands_for_event    await self._invoke_command(command, context, positional_args, keyword_arg)  File "/usr/local/lib/python3.8/site-packages/lightbulb/command_handler.py", line 788, in _invoke_command    await command.invoke(context)  File "/usr/local/lib/python3.8/site-packages/lightbulb/commands.py", line 495, in invoke    return await self._callback(context, *new_args, **kwargs)  File "/usr/local/lib/python3.8/site-packages/lightbulb/help.py", line 124, in _help_cmd    await ctx.bot.help_command.resolve_help_obj(ctx, obj)  File "/usr/local/lib/python3.8/site-packages/lightbulb/help.py", line 175, in resolve_help_obj    await self.send_help_overview(context)  File "/home/ahnaf/Documents/shikamaru-bot/shikamaru/plugins/help.py", line 20, in send_help_overview    for plugin in plugins:lightbulb.errors.CommandInvocationError: TypeError: 'NoneType' object is not iterable"
2020-09-29 17:34:02 [Command Error] User: "Ahnaf#4346", Message: "oof.cat", Error: "AttributeError: 'Context' object has no attribute 'send'", Traceback: "Traceback (most recent call last):  File "/usr/local/lib/python3.8/site-packages/lightbulb/command_handler.py", line 852, in process_commands_for_event    await self._invoke_command(command, context, positional_args, keyword_arg)  File "/usr/local/lib/python3.8/site-packages/lightbulb/command_handler.py", line 788, in _invoke_command    await command.invoke(context)  File "/usr/local/lib/python3.8/site-packages/lightbulb/commands.py", line 88, in invoke    return await self._callback(instance, context, *new_args, **kwargs)  File "/home/ahnaf/Documents/shikamaru-bot/shikamaru/plugins/fun.py", line 42, in cat    await ctx.send(embed=discord.Embed(title='Random Cat').set_image(url=js[0]['url']))lightbulb.errors.CommandInvocationError: AttributeError: 'Context' object has no attribute 'send'"
2020-09-29 17:35:10 [Command Error] User: "Ahnaf#4346", Message: "oof.cat", Error: "AttributeError: 'Context' object has no attribute 'send'", Traceback: "Traceback (most recent call last):  File "/usr/local/lib/python3.8/site-packages/lightbulb/command_handler.py", line 852, in process_commands_for_event    await self._invoke_command(command, context, positional_args, keyword_arg)  File "/usr/local/lib/python3.8/site-packages/lightbulb/command_handler.py", line 788, in _invoke_command    await command.invoke(context)  File "/usr/local/lib/python3.8/site-packages/lightbulb/commands.py", line 88, in invoke    return await self._callback(instance, context, *new_args, **kwargs)  File "/home/ahnaf/Documents/shikamaru-bot/shikamaru/plugins/fun.py", line 42, in cat    await ctx.send(embed=hikari.Embed(title=random.choice(dog_titles), color="#dffc03").set_image(js[0]['url']))lightbulb.errors.CommandInvocationError: AttributeError: 'Context' object has no attribute 'send'"
2020-09-29 17:53:34 [Command Error] User: "Ahnaf#4346", Message: "sh!meme", Error: "TypeError: get_meme() takes 0 positional arguments but 1 was given", Traceback: "Traceback (most recent call last):  File "/usr/local/lib/python3.8/site-packages/lightbulb/command_handler.py", line 852, in process_commands_for_event    await self._invoke_command(command, context, positional_args, keyword_arg)  File "/usr/local/lib/python3.8/site-packages/lightbulb/command_handler.py", line 788, in _invoke_command    await command.invoke(context)  File "/usr/local/lib/python3.8/site-packages/lightbulb/commands.py", line 88, in invoke    return await self._callback(instance, context, *new_args, **kwargs)  File "/home/ahnaf/Documents/shikamaru-bot/shikamaru/plugins/fun.py", line 41, in meme    json_data = await self.get_meme()lightbulb.errors.CommandInvocationError: TypeError: get_meme() takes 0 positional arguments but 1 was given"
2020-09-29 17:53:54 [Command Error] User: "Ahnaf#4346", Message: "sh!meme", Error: "TypeError: unsupported operand type(s) for -: 'str' and 'str'", Traceback: "Traceback (most recent call last):  File "/usr/local/lib/python3.8/site-packages/lightbulb/command_handler.py", line 852, in process_commands_for_event    await self._invoke_command(command, context, positional_args, keyword_arg)  File "/usr/local/lib/python3.8/site-packages/lightbulb/command_handler.py", line 788, in _invoke_command    await command.invoke(context)  File "/usr/local/lib/python3.8/site-packages/lightbulb/commands.py", line 88, in invoke    return await self._callback(instance, context, *new_args, **kwargs)  File "/home/ahnaf/Documents/shikamaru-bot/shikamaru/plugins/fun.py", line 41, in meme    json_data = await self.get_meme()  File "/home/ahnaf/Documents/shikamaru-bot/shikamaru/plugins/fun.py", line 32, in get_meme    sub_reddit = self.bot.config['meme_subreddit'] - "https://reddit.com/r/"lightbulb.errors.CommandInvocationError: TypeError: unsupported operand type(s) for -: 'str' and 'str'"
2020-09-29 17:54:28 [Command Error] User: "Ahnaf#4346", Message: "sh!meme", Error: "NameError: name 'fetch' is not defined", Traceback: "Traceback (most recent call last):  File "/usr/local/lib/python3.8/site-packages/lightbulb/command_handler.py", line 852, in process_commands_for_event    await self._invoke_command(command, context, positional_args, keyword_arg)  File "/usr/local/lib/python3.8/site-packages/lightbulb/command_handler.py", line 788, in _invoke_command    await command.invoke(context)  File "/usr/local/lib/python3.8/site-packages/lightbulb/commands.py", line 88, in invoke    return await self._callback(instance, context, *new_args, **kwargs)  File "/home/ahnaf/Documents/shikamaru-bot/shikamaru/plugins/fun.py", line 41, in meme    json_data = await self.get_meme()  File "/home/ahnaf/Documents/shikamaru-bot/shikamaru/plugins/fun.py", line 34, in get_meme    r = await fetch(session, "https://meme-api.herokuapp.com/gimme/" + sub_reddit)lightbulb.errors.CommandInvocationError: NameError: name 'fetch' is not defined"
2020-09-29 17:55:40 [Command Error] User: "Ahnaf#4346", Message: "sh!meme", Error: "NameError: name 'json' is not defined", Traceback: "Traceback (most recent call last):  File "/usr/local/lib/python3.8/site-packages/lightbulb/command_handler.py", line 852, in process_commands_for_event    await self._invoke_command(command, context, positional_args, keyword_arg)  File "/usr/local/lib/python3.8/site-packages/lightbulb/command_handler.py", line 788, in _invoke_command    await command.invoke(context)  File "/usr/local/lib/python3.8/site-packages/lightbulb/commands.py", line 88, in invoke    return await self._callback(instance, context, *new_args, **kwargs)  File "/home/ahnaf/Documents/shikamaru-bot/shikamaru/plugins/fun.py", line 42, in meme    json_data = await self.get_meme()  File "/home/ahnaf/Documents/shikamaru-bot/shikamaru/plugins/fun.py", line 36, in get_meme    r = json.loads(r)lightbulb.errors.CommandInvocationError: NameError: name 'json' is not defined"
2020-09-29 18:04:08 [Command Error] User: "Ahnaf#4346", Message: "sh!meme", Error: "ValueError: Could not transform '' into a Color object", Traceback: "Traceback (most recent call last):  File "/usr/local/lib/python3.8/site-packages/lightbulb/command_handler.py", line 852, in process_commands_for_event    await self._invoke_command(command, context, positional_args, keyword_arg)  File "/usr/local/lib/python3.8/site-packages/lightbulb/command_handler.py", line 788, in _invoke_command    await command.invoke(context)  File "/usr/local/lib/python3.8/site-packages/lightbulb/commands.py", line 88, in invoke    return await self._callback(instance, context, *new_args, **kwargs)  File "/home/ahnaf/Documents/shikamaru-bot/shikamaru/plugins/fun.py", line 43, in meme    em = hikari.Embed(title=json_data["title"], color="")  File "/usr/local/lib/python3.8/site-packages/hikari/embeds.py", line 318, in __init__    self._color = colors.Color.of(color)  File "/usr/local/lib/python3.8/site-packages/hikari/colors.py", line 533, in of    raise ValueError(f"Could not transform {value!r} into a {cls.__qualname__} object")lightbulb.errors.CommandInvocationError: ValueError: Could not transform '' into a Color object"
2020-09-29 18:04:39 [Command Error] User: "Ahnaf#4346", Message: "sh!meme", Error: "TypeError: set_image() got some positional-only arguments passed as keyword arguments: 'image'", Traceback: "Traceback (most recent call last):  File "/usr/local/lib/python3.8/site-packages/lightbulb/command_handler.py", line 852, in process_commands_for_event    await self._invoke_command(command, context, positional_args, keyword_arg)  File "/usr/local/lib/python3.8/site-packages/lightbulb/command_handler.py", line 788, in _invoke_command    await command.invoke(context)  File "/usr/local/lib/python3.8/site-packages/lightbulb/commands.py", line 88, in invoke    return await self._callback(instance, context, *new_args, **kwargs)  File "/home/ahnaf/Documents/shikamaru-bot/shikamaru/plugins/fun.py", line 46, in meme    em.set_image(image=json_data["url"])lightbulb.errors.CommandInvocationError: TypeError: set_image() got some positional-only arguments passed as keyword arguments: 'image'"
2020-09-29 19:15:38 [Command Error] User: "Ahnaf#4346", Message: "sh!help", Error: "ClientConnectorError: Cannot connect to host discord.com:443 ssl:default [Name or service not known]", Traceback: "Traceback (most recent call last):  File "/usr/local/lib/python3.8/site-packages/lightbulb/command_handler.py", line 852, in process_commands_for_event    await self._invoke_command(command, context, positional_args, keyword_arg)  File "/usr/local/lib/python3.8/site-packages/lightbulb/command_handler.py", line 788, in _invoke_command    await command.invoke(context)  File "/usr/local/lib/python3.8/site-packages/lightbulb/commands.py", line 495, in invoke    return await self._callback(context, *new_args, **kwargs)  File "/usr/local/lib/python3.8/site-packages/lightbulb/help.py", line 124, in _help_cmd    await ctx.bot.help_command.resolve_help_obj(ctx, obj)  File "/usr/local/lib/python3.8/site-packages/lightbulb/help.py", line 175, in resolve_help_obj    await self.send_help_overview(context)  File "/home/ahnaf/Documents/shikamaru-bot/shikamaru/plugins/help.py", line 28, in send_help_overview    await ctx.reply(embed=em)  File "/usr/local/lib/python3.8/site-packages/lightbulb/context.py", line 194, in reply    return await self.message.reply(*args, **kwargs)  File "/usr/local/lib/python3.8/site-packages/hikari/messages.py", line 666, in reply    return await self.app.rest.create_message(  File "/usr/local/lib/python3.8/site-packages/hikari/impl/rest.py", line 1062, in create_message    raw_response = await self._request(route, json=body)  File "/usr/local/lib/python3.8/site-packages/hikari/impl/rest.py", line 559, in _request    response = await session.request(  File "/usr/local/lib/python3.8/site-packages/aiohttp/client.py", line 480, in _request    conn = await self._connector.connect(  File "/usr/local/lib/python3.8/site-packages/aiohttp/connector.py", line 523, in connect    proto = await self._create_connection(req, traces, timeout)  File "/usr/local/lib/python3.8/site-packages/aiohttp/connector.py", line 858, in _create_connection    _, proto = await self._create_direct_connection(  File "/usr/local/lib/python3.8/site-packages/aiohttp/connector.py", line 971, in _create_direct_connection    raise ClientConnectorError(req.connection_key, exc) from exclightbulb.errors.CommandInvocationError: ClientConnectorError: Cannot connect to host discord.com:443 ssl:default [Name or service not known]"
2020-09-29 19:49:34 [Command Error] User: "Ahnaf#4346", Message: "sh!qrcode https://discord.com", Error: "NameError: name 'data' is not defined", Traceback: "Traceback (most recent call last):  File "/usr/local/lib/python3.8/site-packages/lightbulb/command_handler.py", line 852, in process_commands_for_event    await self._invoke_command(command, context, positional_args, keyword_arg)  File "/usr/local/lib/python3.8/site-packages/lightbulb/command_handler.py", line 786, in _invoke_command    await command.invoke(context, *args)  File "/usr/local/lib/python3.8/site-packages/lightbulb/commands.py", line 88, in invoke    return await self._callback(instance, context, *new_args, **kwargs)  File "/home/ahnaf/Documents/shikamaru-bot/shikamaru/plugins/fun.py", line 84, in qrcode    if data:lightbulb.errors.CommandInvocationError: NameError: name 'data' is not defined"
2020-09-29 19:50:05 [Command Error] User: "Ahnaf#4346", Message: "sh!qrcode https://discord.com", Error: "NameError: name 'data' is not defined", Traceback: "Traceback (most recent call last):  File "/usr/local/lib/python3.8/site-packages/lightbulb/command_handler.py", line 852, in process_commands_for_event    await self._invoke_command(command, context, positional_args, keyword_arg)  File "/usr/local/lib/python3.8/site-packages/lightbulb/command_handler.py", line 786, in _invoke_command    await command.invoke(context, *args)  File "/usr/local/lib/python3.8/site-packages/lightbulb/commands.py", line 88, in invoke    return await self._callback(instance, context, *new_args, **kwargs)  File "/home/ahnaf/Documents/shikamaru-bot/shikamaru/plugins/fun.py", line 85, in qrcode    await self.qrickit(ctx, data)lightbulb.errors.CommandInvocationError: NameError: name 'data' is not defined"
2020-09-29 19:59:23 [Command Error] User: "Ahnaf#4346", Message: "sh!fortune", Error: "fortune", Traceback: "Traceback (most recent call last):  File "/usr/local/lib/python3.8/site-packages/lightbulb/command_handler.py", line 813, in process_commands_for_event    command = self._validate_command_exists(invoked_with)  File "/usr/local/lib/python3.8/site-packages/lightbulb/command_handler.py", line 730, in _validate_command_exists    raise errors.CommandNotFound(invoked_with)lightbulb.errors.CommandNotFound: fortune"
2020-09-29 20:26:37 [Command Error] User: "Ahnaf#4346", Message: "sh!qrcode espy is bad", Error: "BadRequestError: Bad Request 400: 'Invalid Form Body' for https://discord.com/api/v8/channels/339112602867204097/messages", Traceback: "Traceback (most recent call last):  File "/usr/local/lib/python3.8/site-packages/lightbulb/command_handler.py", line 852, in process_commands_for_event    await self._invoke_command(command, context, positional_args, keyword_arg)  File "/usr/local/lib/python3.8/site-packages/lightbulb/command_handler.py", line 784, in _invoke_command    await command.invoke(context, *args, **kwarg)  File "/usr/local/lib/python3.8/site-packages/lightbulb/commands.py", line 88, in invoke    return await self._callback(instance, context, *new_args, **kwargs)  File "/home/ahnaf/Documents/shikamaru-bot/shikamaru/plugins/fun.py", line 86, in qrcode    await self.qrickit(ctx, url)  File "/home/ahnaf/Documents/shikamaru-bot/shikamaru/plugins/fun.py", line 39, in qrickit    await ctx.reply(embed=em)  File "/usr/local/lib/python3.8/site-packages/lightbulb/context.py", line 194, in reply    return await self.message.reply(*args, **kwargs)  File "/usr/local/lib/python3.8/site-packages/hikari/messages.py", line 666, in reply    return await self.app.rest.create_message(  File "/usr/local/lib/python3.8/site-packages/hikari/impl/rest.py", line 1062, in create_message    raw_response = await self._request(route, json=body)  File "/usr/local/lib/python3.8/site-packages/hikari/impl/rest.py", line 601, in _request    await self._handle_error_response(response)  File "/usr/local/lib/python3.8/site-packages/hikari/impl/rest.py", line 622, in _handle_error_response    raise await net.generate_error_response(response)lightbulb.errors.CommandInvocationError: BadRequestError: Bad Request 400: 'Invalid Form Body' for https://discord.com/api/v8/channels/339112602867204097/messages"
2020-09-29 20:32:15 [Command Error] User: "Ahnaf#4346", Message: "sh!qrcode espy is bad boi but ", Error: "BadRequestError: Bad Request 400: 'Invalid Form Body' for https://discord.com/api/v8/channels/339112602867204097/messages", Traceback: "Traceback (most recent call last):  File "/usr/local/lib/python3.8/site-packages/lightbulb/command_handler.py", line 852, in process_commands_for_event    await self._invoke_command(command, context, positional_args, keyword_arg)  File "/usr/local/lib/python3.8/site-packages/lightbulb/command_handler.py", line 784, in _invoke_command    await command.invoke(context, *args, **kwarg)  File "/usr/local/lib/python3.8/site-packages/lightbulb/commands.py", line 88, in invoke    return await self._callback(instance, context, *new_args, **kwargs)  File "/home/ahnaf/Documents/shikamaru-bot/shikamaru/plugins/fun.py", line 86, in qrcode    await self.qrickit(ctx, url)  File "/home/ahnaf/Documents/shikamaru-bot/shikamaru/plugins/fun.py", line 39, in qrickit    await ctx.reply(embed=em)  File "/usr/local/lib/python3.8/site-packages/lightbulb/context.py", line 194, in reply    return await self.message.reply(*args, **kwargs)  File "/usr/local/lib/python3.8/site-packages/hikari/messages.py", line 666, in reply    return await self.app.rest.create_message(  File "/usr/local/lib/python3.8/site-packages/hikari/impl/rest.py", line 1062, in create_message    raw_response = await self._request(route, json=body)  File "/usr/local/lib/python3.8/site-packages/hikari/impl/rest.py", line 601, in _request    await self._handle_error_response(response)  File "/usr/local/lib/python3.8/site-packages/hikari/impl/rest.py", line 622, in _handle_error_response    raise await net.generate_error_response(response)lightbulb.errors.CommandInvocationError: BadRequestError: Bad Request 400: 'Invalid Form Body' for https://discord.com/api/v8/channels/339112602867204097/messages"
2020-09-30 10:39:27 [Command Error] User: "Ahnaf#4346", Message: "sh!about", Error: "NameError: name 'aiofiles' is not defined", Traceback: "Traceback (most recent call last):  File "/usr/local/lib/python3.8/site-packages/lightbulb/command_handler.py", line 852, in process_commands_for_event    await self._invoke_command(command, context, positional_args, keyword_arg)  File "/usr/local/lib/python3.8/site-packages/lightbulb/command_handler.py", line 788, in _invoke_command    await command.invoke(context)  File "/usr/local/lib/python3.8/site-packages/lightbulb/commands.py", line 88, in invoke    return await self._callback(instance, context, *new_args, **kwargs)  File "/home/ahnaf/Documents/shikamaru-bot/shikamaru/plugins/info.py", line 59, in about    async with aiofiles.open("shikamaru/txt/commands_ran.txt", "r") as f:lightbulb.errors.CommandInvocationError: NameError: name 'aiofiles' is not defined"
2020-10-01 13:42:05 [Command Error] User: "Ahnaf#4346", Message: "sh!codefor help", Error: "NameError: name 'context' is not defined", Traceback: "Traceback (most recent call last):  File "/usr/local/lib/python3.8/site-packages/lightbulb/command_handler.py", line 852, in process_commands_for_event    await self._invoke_command(command, context, positional_args, keyword_arg)  File "/usr/local/lib/python3.8/site-packages/lightbulb/command_handler.py", line 786, in _invoke_command    await command.invoke(context, *args)  File "/usr/local/lib/python3.8/site-packages/lightbulb/commands.py", line 88, in invoke    return await self._callback(instance, context, *new_args, **kwargs)  File "/home/ahnaf/Documents/shikamaru-bot/shikamaru/plugins/superuser.py", line 121, in getcode    navigator = EmbedNavigator(paginator.build_pages())  File "/usr/local/lib/python3.8/site-packages/lightbulb/utils/nav.py", line 86, in __init__    self.pages: typing.Sequence[T] = tuple(pages)  File "/usr/local/lib/python3.8/site-packages/lightbulb/utils/pag.py", line 95, in build_pages    yield self._page_factory(i, page)  File "/home/ahnaf/Documents/shikamaru-bot/shikamaru/plugins/superuser.py", line 117, in make_embed    icon=context.author.avatar_url,lightbulb.errors.CommandInvocationError: NameError: name 'context' is not defined"
2020-10-01 13:43:31 [Command Error] User: "Ahnaf#4346", Message: "sh!codefor CustomHelp", Error: "Failed converting CustomHelp with converter: pluginish_converter", Traceback: "Traceback (most recent call last):  File "/usr/local/lib/python3.8/site-packages/lightbulb/commands.py", line 456, in _convert_args    new_arg = await self._handle_types(arg, details)  File "/usr/local/lib/python3.8/site-packages/lightbulb/commands.py", line 439, in _handle_types    new_arg = await maybe_await(details.annotation, arg)  File "/usr/local/lib/python3.8/site-packages/lightbulb/utils/__init__.py", line 35, in maybe_await    result = await result  File "/home/ahnaf/Documents/shikamaru-bot/shikamaru/utils/converters.py", line 16, in pluginish_converter    raise ConverterFailure(f"Failed to get plugin or command with arg {arg}")lightbulb.errors.ConverterFailure: Failed to get plugin or command with arg CustomHelpDuring handling of the above exception, another exception occurred:Traceback (most recent call last):  File "/usr/local/lib/python3.8/site-packages/lightbulb/command_handler.py", line 852, in process_commands_for_event    await self._invoke_command(command, context, positional_args, keyword_arg)  File "/usr/local/lib/python3.8/site-packages/lightbulb/command_handler.py", line 786, in _invoke_command    await command.invoke(context, *args)  File "/usr/local/lib/python3.8/site-packages/lightbulb/commands.py", line 78, in invoke    new_args = await self._convert_args(context, args, list(self.arg_details.args.values())[2 : len(args) + 2])  File "/usr/local/lib/python3.8/site-packages/lightbulb/commands.py", line 464, in _convert_args    raise errors.ConverterFailure(lightbulb.errors.ConverterFailure: Failed converting CustomHelp with converter: pluginish_converter"
2020-10-01 13:44:38 [Command Error] User: "Ahnaf#4346", Message: "sh!exec
```py
with open("shika", Error: "BadRequestError: Bad Request 400: 'Invalid Form Body' for https://discord.com/api/v8/channels/755759163061305374/messages", Traceback: "Traceback (most recent call last):  File "/usr/local/lib/python3.8/site-packages/lightbulb/command_handler.py", line 852, in process_commands_for_event    await self._invoke_command(command, context, positional_args, keyword_arg)  File "/usr/local/lib/python3.8/site-packages/lightbulb/command_handler.py", line 788, in _invoke_command    await command.invoke(context)  File "/usr/local/lib/python3.8/site-packages/lightbulb/commands.py", line 88, in invoke    return await self._callback(instance, context, *new_args, **kwargs)  File "/home/ahnaf/Documents/shikamaru-bot/shikamaru/plugins/superuser.py", line 89, in code    await ctx.reply(embed=em)  File "/usr/local/lib/python3.8/site-packages/lightbulb/context.py", line 194, in reply    return await self.message.reply(*args, **kwargs)  File "/usr/local/lib/python3.8/site-packages/hikari/messages.py", line 666, in reply    return await self.app.rest.create_message(  File "/usr/local/lib/python3.8/site-packages/hikari/impl/rest.py", line 1062, in create_message    raw_response = await self._request(route, json=body)  File "/usr/local/lib/python3.8/site-packages/hikari/impl/rest.py", line 601, in _request    await self._handle_error_response(response)  File "/usr/local/lib/python3.8/site-packages/hikari/impl/rest.py", line 622, in _handle_error_response    raise await net.generate_error_response(response)lightbulb.errors.CommandInvocationError: BadRequestError: Bad Request 400: 'Invalid Form Body' for https://discord.com/api/v8/channels/755759163061305374/messages"
2020-10-01 13:45:02 [Command Error] User: "Ahnaf#4346", Message: "sh!exec
```py
print("Oof")
wit", Error: "BadRequestError: Bad Request 400: 'Invalid Form Body' for https://discord.com/api/v8/channels/755759163061305374/messages", Traceback: "Traceback (most recent call last):  File "/usr/local/lib/python3.8/site-packages/lightbulb/command_handler.py", line 852, in process_commands_for_event    await self._invoke_command(command, context, positional_args, keyword_arg)  File "/usr/local/lib/python3.8/site-packages/lightbulb/command_handler.py", line 788, in _invoke_command    await command.invoke(context)  File "/usr/local/lib/python3.8/site-packages/lightbulb/commands.py", line 88, in invoke    return await self._callback(instance, context, *new_args, **kwargs)  File "/home/ahnaf/Documents/shikamaru-bot/shikamaru/plugins/superuser.py", line 89, in code    await ctx.reply(embed=em)  File "/usr/local/lib/python3.8/site-packages/lightbulb/context.py", line 194, in reply    return await self.message.reply(*args, **kwargs)  File "/usr/local/lib/python3.8/site-packages/hikari/messages.py", line 666, in reply    return await self.app.rest.create_message(  File "/usr/local/lib/python3.8/site-packages/hikari/impl/rest.py", line 1062, in create_message    raw_response = await self._request(route, json=body)  File "/usr/local/lib/python3.8/site-packages/hikari/impl/rest.py", line 601, in _request    await self._handle_error_response(response)  File "/usr/local/lib/python3.8/site-packages/hikari/impl/rest.py", line 622, in _handle_error_response    raise await net.generate_error_response(response)lightbulb.errors.CommandInvocationError: BadRequestError: Bad Request 400: 'Invalid Form Body' for https://discord.com/api/v8/channels/755759163061305374/messages"
2020-10-01 14:00:42 [Command Error] User: "Ahnaf#4346", Message: "sh!pig", Error: "pig", Traceback: "Traceback (most recent call last):  File "/usr/local/lib/python3.8/site-packages/lightbulb/command_handler.py", line 813, in process_commands_for_event    command = self._validate_command_exists(invoked_with)  File "/usr/local/lib/python3.8/site-packages/lightbulb/command_handler.py", line 730, in _validate_command_exists    raise errors.CommandNotFound(invoked_with)lightbulb.errors.CommandNotFound: pig"
2020-10-01 15:41:11 [Command Error] User: "Ahnaf#4346", Message: "sh!info", Error: "info", Traceback: "Traceback (most recent call last):  File "/usr/local/lib/python3.8/site-packages/lightbulb/command_handler.py", line 813, in process_commands_for_event    command = self._validate_command_exists(invoked_with)  File "/usr/local/lib/python3.8/site-packages/lightbulb/command_handler.py", line 730, in _validate_command_exists    raise errors.CommandNotFound(invoked_with)lightbulb.errors.CommandNotFound: info"
2020-10-01 15:45:58 [Command Error] User: "Ahnaf#4346", Message: "sh!about", Error: "NameError: name 'platform' is not defined", Traceback: "Traceback (most recent call last):  File "/usr/local/lib/python3.8/site-packages/lightbulb/command_handler.py", line 852, in process_commands_for_event    await self._invoke_command(command, context, positional_args, keyword_arg)  File "/usr/local/lib/python3.8/site-packages/lightbulb/command_handler.py", line 788, in _invoke_command    await command.invoke(context)  File "/usr/local/lib/python3.8/site-packages/lightbulb/commands.py", line 88, in invoke    return await self._callback(instance, context, *new_args, **kwargs)  File "/home/ahnaf/Documents/shikamaru-bot/shikamaru/plugins/info.py", line 75, in about    osinfo = platform.uname()lightbulb.errors.CommandInvocationError: NameError: name 'platform' is not defined"
2020-10-01 15:56:19 [Command Error] User: "Ahnaf#4346", Message: "sh!oof", Error: "AttributeError: 'Bot' object has no attribute 'loop'", Traceback: "Traceback (most recent call last):  File "/usr/local/lib/python3.8/site-packages/lightbulb/command_handler.py", line 852, in process_commands_for_event    await self._invoke_command(command, context, positional_args, keyword_arg)  File "/usr/local/lib/python3.8/site-packages/lightbulb/command_handler.py", line 788, in _invoke_command    await command.invoke(context)  File "/usr/local/lib/python3.8/site-packages/lightbulb/commands.py", line 88, in invoke    return await self._callback(instance, context, *new_args, **kwargs)  File "/home/ahnaf/Documents/shikamaru-bot/shikamaru/plugins/info.py", line 106, in oof    print(self.bot.loop)lightbulb.errors.CommandInvocationError: AttributeError: 'Bot' object has no attribute 'loop'"
2020-10-01 16:18:30 [Command Error] User: "Ahnaf#4346", Message: "sh!translate oof", Error: "NameError: name 'asyncio' is not defined", Traceback: "Traceback (most recent call last):  File "/usr/local/lib/python3.8/site-packages/lightbulb/command_handler.py", line 852, in process_commands_for_event    await self._invoke_command(command, context, positional_args, keyword_arg)  File "/usr/local/lib/python3.8/site-packages/lightbulb/command_handler.py", line 784, in _invoke_command    await command.invoke(context, *args, **kwarg)  File "/usr/local/lib/python3.8/site-packages/lightbulb/commands.py", line 88, in invoke    return await self._callback(instance, context, *new_args, **kwargs)  File "/home/ahnaf/Documents/shikamaru-bot/shikamaru/plugins/fun.py", line 159, in translate    loop = asyncio.get_running_loop(self.bot.executor)lightbulb.errors.CommandInvocationError: NameError: name 'asyncio' is not defined"
2020-10-01 16:19:01 [Command Error] User: "Ahnaf#4346", Message: "sh!translate oof", Error: "TypeError: get_running_loop() takes no arguments (1 given)", Traceback: "Traceback (most recent call last):  File "/usr/local/lib/python3.8/site-packages/lightbulb/command_handler.py", line 852, in process_commands_for_event    await self._invoke_command(command, context, positional_args, keyword_arg)  File "/usr/local/lib/python3.8/site-packages/lightbulb/command_handler.py", line 784, in _invoke_command    await command.invoke(context, *args, **kwarg)  File "/usr/local/lib/python3.8/site-packages/lightbulb/commands.py", line 88, in invoke    return await self._callback(instance, context, *new_args, **kwargs)  File "/home/ahnaf/Documents/shikamaru-bot/shikamaru/plugins/fun.py", line 160, in translate    loop = asyncio.get_running_loop(self.bot.executor)lightbulb.errors.CommandInvocationError: TypeError: get_running_loop() takes no arguments (1 given)"
2020-10-02 15:58:09 [Command Error] User: "Ahnaf#4346", Message: "sh!punch", Error: "AttributeError: 'Context' object has no attribute 'send'", Traceback: "Traceback (most recent call last):  File "/usr/local/lib/python3.8/site-packages/lightbulb/command_handler.py", line 852, in process_commands_for_event    await self._invoke_command(command, context, positional_args, keyword_arg)  File "/usr/local/lib/python3.8/site-packages/lightbulb/command_handler.py", line 788, in _invoke_command    await command.invoke(context)  File "/usr/local/lib/python3.8/site-packages/lightbulb/commands.py", line 88, in invoke    return await self._callback(instance, context, *new_args, **kwargs)  File "/home/ahnaf/Documents/shikamaru-bot/shikamaru/plugins/actions.py", line 27, in punch    await ctx.send(f"You can't punch air {ctx.message.author.mention}!")lightbulb.errors.CommandInvocationError: AttributeError: 'Context' object has no attribute 'send'"
2020-10-02 15:59:13 [Command Error] User: "Ahnaf#4346", Message: "sh!punch Shikamaru", Error: "TypeError: __init__() takes 1 positional argument but 2 were given", Traceback: "Traceback (most recent call last):  File "/usr/local/lib/python3.8/site-packages/lightbulb/command_handler.py", line 852, in process_commands_for_event    await self._invoke_command(command, context, positional_args, keyword_arg)  File "/usr/local/lib/python3.8/site-packages/lightbulb/command_handler.py", line 786, in _invoke_command    await command.invoke(context, *args)  File "/usr/local/lib/python3.8/site-packages/lightbulb/commands.py", line 78, in invoke    new_args = await self._convert_args(context, args, list(self.arg_details.args.values())[2 : len(args) + 2])  File "/usr/local/lib/python3.8/site-packages/lightbulb/commands.py", line 456, in _convert_args    new_arg = await self._handle_types(arg, details)  File "/usr/local/lib/python3.8/site-packages/lightbulb/commands.py", line 439, in _handle_types    new_arg = await maybe_await(details.annotation, arg)  File "/usr/local/lib/python3.8/site-packages/lightbulb/utils/__init__.py", line 33, in maybe_await    result = callable_(*args, **kwargs)lightbulb.errors.CommandInvocationError: TypeError: __init__() takes 1 positional argument but 2 were given"
2020-10-02 16:05:23 [Command Error] User: "Ahnaf#4346", Message: "sh!run Shikamaru", Error: "FileNotFoundError: [Errno 2] No such file or directory: 'shikamaru/txt/run_gifs.txt'", Traceback: "Traceback (most recent call last):  File "/usr/local/lib/python3.8/site-packages/lightbulb/command_handler.py", line 852, in process_commands_for_event    await self._invoke_command(command, context, positional_args, keyword_arg)  File "/usr/local/lib/python3.8/site-packages/lightbulb/command_handler.py", line 786, in _invoke_command    await command.invoke(context, *args)  File "/usr/local/lib/python3.8/site-packages/lightbulb/commands.py", line 88, in invoke    return await self._callback(instance, context, *new_args, **kwargs)  File "/home/ahnaf/Documents/shikamaru-bot/shikamaru/plugins/actions.py", line 33, in run    async with aiofiles.open("shikamaru/txt/run_gifs.txt", mode="r") as f:  File "/usr/local/lib/python3.8/site-packages/aiofiles/base.py", line 75, in __aenter__    self._obj = await self._coro  File "/usr/local/lib/python3.8/site-packages/aiofiles/threadpool/__init__.py", line 80, in _open    f = yield from loop.run_in_executor(executor, cb)  File "/usr/lib64/python3.8/concurrent/futures/thread.py", line 57, in run    result = self.fn(*self.args, **self.kwargs)lightbulb.errors.CommandInvocationError: FileNotFoundError: [Errno 2] No such file or directory: 'shikamaru/txt/run_gifs.txt'"
2020-10-02 16:06:23 [Command Error] User: "Ahnaf#4346", Message: "sh!run Shikamaru", Error: "NameError: name 'em' is not defined", Traceback: "Traceback (most recent call last):  File "/usr/local/lib/python3.8/site-packages/lightbulb/command_handler.py", line 852, in process_commands_for_event    await self._invoke_command(command, context, positional_args, keyword_arg)  File "/usr/local/lib/python3.8/site-packages/lightbulb/command_handler.py", line 786, in _invoke_command    await command.invoke(context, *args)  File "/usr/local/lib/python3.8/site-packages/lightbulb/commands.py", line 88, in invoke    return await self._callback(instance, context, *new_args, **kwargs)  File "/home/ahnaf/Documents/shikamaru-bot/shikamaru/plugins/actions.py", line 46, in run    em.timestamp = datetime.datetime.now().astimezone()lightbulb.errors.CommandInvocationError: NameError: name 'em' is not defined"
2020-10-02 16:15:03 [Command Error] User: "Ahnaf#4346", Message: "sh!roast thommo", Error: "FileNotFoundError: [Errno 2] No such file or directory: 'shikamaru/txt/roasts.txt'", Traceback: "Traceback (most recent call last):  File "/usr/local/lib/python3.8/site-packages/lightbulb/command_handler.py", line 852, in process_commands_for_event    await self._invoke_command(command, context, positional_args, keyword_arg)  File "/usr/local/lib/python3.8/site-packages/lightbulb/command_handler.py", line 784, in _invoke_command    await command.invoke(context, *args, **kwarg)  File "/usr/local/lib/python3.8/site-packages/lightbulb/commands.py", line 88, in invoke    return await self._callback(instance, context, *new_args, **kwargs)  File "/home/ahnaf/Documents/shikamaru-bot/shikamaru/plugins/fun.py", line 159, in roast    with open("shikamaru/txt/roasts.txt") as f:lightbulb.errors.CommandInvocationError: FileNotFoundError: [Errno 2] No such file or directory: 'shikamaru/txt/roasts.txt'"
