2020-09-28 13:41:35 [Command Error] User: "Ahnaf#4346", Message: "sh!wrong", Error: "ZeroDivisionError: division by zero", Traceback: "Traceback (most recent call last):  File "C:\Users\HOME\AppData\Local\Programs\Python\Python38-32\lib\site-packages\lightbulb\command_handler.py", line 852, in process_commands_for_event    await self._invoke_command(command, context, positional_args, keyword_arg)  File "C:\Users\HOME\AppData\Local\Programs\Python\Python38-32\lib\site-packages\lightbulb\command_handler.py", line 788, in _invoke_command    await command.invoke(context)  File "C:\Users\HOME\AppData\Local\Programs\Python\Python38-32\lib\site-packages\lightbulb\commands.py", line 495, in invoke    return await self._callback(context, *new_args, **kwargs)  File "F:\Ahnaf's Folder\Shikamaru Bot\shikamaru\bot.py", line 20, in wrong    await ctx.reply(1/0)lightbulb.errors.CommandInvocationError: ZeroDivisionError: division by zero"
2020-09-28 14:59:13 [Command Error] User: "Ahnaf#4346", Message: "sh!github", Error: "github", Traceback: "Traceback (most recent call last):  File "C:\Users\HOME\AppData\Local\Programs\Python\Python38-32\lib\site-packages\lightbulb\command_handler.py", line 840, in process_commands_for_event    positional_args, keyword_arg = self.resolve_args_for_command(command, final_args)  File "C:\Users\HOME\AppData\Local\Programs\Python\Python38-32\lib\site-packages\lightbulb\command_handler.py", line 768, in resolve_args_for_command    raise errors.NotEnoughArguments(command.name)lightbulb.errors.NotEnoughArguments: github"
2020-09-28 15:01:00 [Command Error] User: "Ahnaf#4346", Message: "sh!help github", Error: "AttributeError: 'str' object has no attribute 'annotation'", Traceback: "Traceback (most recent call last):  File "C:\Users\HOME\AppData\Local\Programs\Python\Python38-32\lib\site-packages\lightbulb\command_handler.py", line 852, in process_commands_for_event    await self._invoke_command(command, context, positional_args, keyword_arg)  File "C:\Users\HOME\AppData\Local\Programs\Python\Python38-32\lib\site-packages\lightbulb\command_handler.py", line 788, in _invoke_command    await command.invoke(context)  File "C:\Users\HOME\AppData\Local\Programs\Python\Python38-32\lib\site-packages\lightbulb\commands.py", line 495, in invoke    return await self._callback(context, *new_args, **kwargs)  File "C:\Users\HOME\AppData\Local\Programs\Python\Python38-32\lib\site-packages\lightbulb\help.py", line 124, in _help_cmd    await ctx.bot.help_command.resolve_help_obj(ctx, obj)  File "C:\Users\HOME\AppData\Local\Programs\Python\Python38-32\lib\site-packages\lightbulb\help.py", line 181, in resolve_help_obj    await self.send_command_help(context, command)  File "F:\Ahnaf's Folder\Shikamaru Bot\shikamaru\plugins\help.py", line 23, in send_command_help    print([i.annotation.__name__ for i in command.arg_details.args])  File "F:\Ahnaf's Folder\Shikamaru Bot\shikamaru\plugins\help.py", line 23, in <listcomp>    print([i.annotation.__name__ for i in command.arg_details.args])lightbulb.errors.CommandInvocationError: AttributeError: 'str' object has no attribute 'annotation'"
2020-09-28 15:31:18 [Command Error] User: "Ahnaf#4346", Message: "sh!help github", Error: "TypeError: __init__() got an unexpected keyword argument 'name'", Traceback: "Traceback (most recent call last):  File "C:\Users\HOME\AppData\Local\Programs\Python\Python38-32\lib\site-packages\lightbulb\command_handler.py", line 852, in process_commands_for_event    await self._invoke_command(command, context, positional_args, keyword_arg)  File "C:\Users\HOME\AppData\Local\Programs\Python\Python38-32\lib\site-packages\lightbulb\command_handler.py", line 788, in _invoke_command    await command.invoke(context)  File "C:\Users\HOME\AppData\Local\Programs\Python\Python38-32\lib\site-packages\lightbulb\commands.py", line 495, in invoke    return await self._callback(context, *new_args, **kwargs)  File "C:\Users\HOME\AppData\Local\Programs\Python\Python38-32\lib\site-packages\lightbulb\help.py", line 124, in _help_cmd    await ctx.bot.help_command.resolve_help_obj(ctx, obj)  File "C:\Users\HOME\AppData\Local\Programs\Python\Python38-32\lib\site-packages\lightbulb\help.py", line 181, in resolve_help_obj    await self.send_command_help(context, command)  File "F:\Ahnaf's Folder\Shikamaru Bot\shikamaru\plugins\help.py", line 23, in send_command_help    em = hikari.Embed(name=f"Help for: {command.name.capitalize()}", color="#ae00ff" )lightbulb.errors.CommandInvocationError: TypeError: __init__() got an unexpected keyword argument 'name'"
2020-09-28 15:32:22 [Command Error] User: "Forbidden#0001", Message: "sh!github", Error: "github", Traceback: "Traceback (most recent call last):  File "C:\Users\HOME\AppData\Local\Programs\Python\Python38-32\lib\site-packages\lightbulb\command_handler.py", line 840, in process_commands_for_event    positional_args, keyword_arg = self.resolve_args_for_command(command, final_args)  File "C:\Users\HOME\AppData\Local\Programs\Python\Python38-32\lib\site-packages\lightbulb\command_handler.py", line 768, in resolve_args_for_command    raise errors.NotEnoughArguments(command.name)lightbulb.errors.NotEnoughArguments: github"
2020-09-28 15:47:40 [Command Error] User: "Ahnaf#4346", Message: "sh!exec
```py
print("Oof")
```", Error: "You are not the owner of this bot", Traceback: "Traceback (most recent call last):  File "C:\Users\HOME\AppData\Local\Programs\Python\Python38-32\lib\site-packages\lightbulb\command_handler.py", line 841, in process_commands_for_event    await self._evaluate_checks(command, context)  File "C:\Users\HOME\AppData\Local\Programs\Python\Python38-32\lib\site-packages\lightbulb\command_handler.py", line 685, in _evaluate_checks    raise failed_checks[0]  File "C:\Users\HOME\AppData\Local\Programs\Python\Python38-32\lib\site-packages\lightbulb\command_handler.py", line 673, in _evaluate_checks    if not await check(context):  File "C:\Users\HOME\AppData\Local\Programs\Python\Python38-32\lib\site-packages\lightbulb\checks.py", line 93, in _owner_only    raise errors.NotOwner("You are not the owner of this bot")lightbulb.errors.NotOwner: You are not the owner of this bot"
2020-09-28 15:50:10 [Command Error] User: "Ahnaf#4346", Message: "sh!exec
```py
print("Oof")
```", Error: "AttributeError: 'SuperUser' object has no attribute 'logger'", Traceback: "Traceback (most recent call last):  File "C:\Users\HOME\AppData\Local\Programs\Python\Python38-32\lib\site-packages\lightbulb\command_handler.py", line 852, in process_commands_for_event    await self._invoke_command(command, context, positional_args, keyword_arg)  File "C:\Users\HOME\AppData\Local\Programs\Python\Python38-32\lib\site-packages\lightbulb\command_handler.py", line 784, in _invoke_command    await command.invoke(context, *args, **kwarg)  File "C:\Users\HOME\AppData\Local\Programs\Python\Python38-32\lib\site-packages\lightbulb\commands.py", line 88, in invoke    return await self._callback(instance, context, *new_args, **kwargs)  File "F:\Ahnaf's Folder\Shikamaru Bot\shikamaru\plugins\superuser.py", line 22, in execute    await body.run()  File "F:\Ahnaf's Folder\Shikamaru Bot\shikamaru\utils\code.py", line 46, in _execute    if logger := getattr(self.context.command.plugin, "logger"):lightbulb.errors.CommandInvocationError: AttributeError: 'SuperUser' object has no attribute 'logger'"
2020-09-28 15:50:28 [Command Error] User: "Ahnaf#4346", Message: "sh!exec
```py
print("Oof")
```", Error: "AttributeError: 'SuperUser' object has no attribute 'logger'", Traceback: "Traceback (most recent call last):  File "C:\Users\HOME\AppData\Local\Programs\Python\Python38-32\lib\site-packages\lightbulb\command_handler.py", line 852, in process_commands_for_event    await self._invoke_command(command, context, positional_args, keyword_arg)  File "C:\Users\HOME\AppData\Local\Programs\Python\Python38-32\lib\site-packages\lightbulb\command_handler.py", line 784, in _invoke_command    await command.invoke(context, *args, **kwarg)  File "C:\Users\HOME\AppData\Local\Programs\Python\Python38-32\lib\site-packages\lightbulb\commands.py", line 88, in invoke    return await self._callback(instance, context, *new_args, **kwargs)  File "F:\Ahnaf's Folder\Shikamaru Bot\shikamaru\plugins\superuser.py", line 22, in execute    await body.run()  File "F:\Ahnaf's Folder\Shikamaru Bot\shikamaru\utils\code.py", line 46, in _execute    if logger := getattr(self.context.command.plugin, "logger"):lightbulb.errors.CommandInvocationError: AttributeError: 'SuperUser' object has no attribute 'logger'"
2020-09-28 15:53:54 [Command Error] User: "Ahnaf#4346", Message: "sh!codefor SuperUser", Error: "NameError: name 'Plugin' is not defined", Traceback: "Traceback (most recent call last):  File "C:\Users\HOME\AppData\Local\Programs\Python\Python38-32\lib\site-packages\lightbulb\command_handler.py", line 852, in process_commands_for_event    await self._invoke_command(command, context, positional_args, keyword_arg)  File "C:\Users\HOME\AppData\Local\Programs\Python\Python38-32\lib\site-packages\lightbulb\command_handler.py", line 786, in _invoke_command    await command.invoke(context, *args)  File "C:\Users\HOME\AppData\Local\Programs\Python\Python38-32\lib\site-packages\lightbulb\commands.py", line 88, in invoke    return await self._callback(instance, context, *new_args, **kwargs)  File "F:\Ahnaf's Folder\Shikamaru Bot\shikamaru\plugins\superuser.py", line 71, in getcode    if isinstance(child, Plugin)lightbulb.errors.CommandInvocationError: NameError: name 'Plugin' is not defined"
2020-09-28 15:55:19 [Command Error] User: "Ahnaf#4346", Message: "sh!exec
```py
print()
```", Error: "AttributeError: 'SuperUser' object has no attribute 'logger'", Traceback: "Traceback (most recent call last):  File "C:\Users\HOME\AppData\Local\Programs\Python\Python38-32\lib\site-packages\lightbulb\command_handler.py", line 852, in process_commands_for_event    await self._invoke_command(command, context, positional_args, keyword_arg)  File "C:\Users\HOME\AppData\Local\Programs\Python\Python38-32\lib\site-packages\lightbulb\command_handler.py", line 784, in _invoke_command    await command.invoke(context, *args, **kwarg)  File "C:\Users\HOME\AppData\Local\Programs\Python\Python38-32\lib\site-packages\lightbulb\commands.py", line 88, in invoke    return await self._callback(instance, context, *new_args, **kwargs)  File "F:\Ahnaf's Folder\Shikamaru Bot\shikamaru\plugins\superuser.py", line 22, in execute    await body.run()  File "F:\Ahnaf's Folder\Shikamaru Bot\shikamaru\utils\code.py", line 46, in _execute    if logger := getattr(self.context.command.plugin, "logger"):lightbulb.errors.CommandInvocationError: AttributeError: 'SuperUser' object has no attribute 'logger'"
2020-09-28 16:03:52 [Command Error] User: "Ahnaf#4346", Message: "sh!exec
```py
print()
```", Error: "NameError: name 'command' is not defined", Traceback: "Traceback (most recent call last):  File "C:\Users\HOME\AppData\Local\Programs\Python\Python38-32\lib\site-packages\lightbulb\command_handler.py", line 852, in process_commands_for_event    await self._invoke_command(command, context, positional_args, keyword_arg)  File "C:\Users\HOME\AppData\Local\Programs\Python\Python38-32\lib\site-packages\lightbulb\command_handler.py", line 788, in _invoke_command    await command.invoke(context)  File "C:\Users\HOME\AppData\Local\Programs\Python\Python38-32\lib\site-packages\lightbulb\commands.py", line 88, in invoke    return await self._callback(instance, context, *new_args, **kwargs)  File "F:\Ahnaf's Folder\Shikamaru Bot\shikamaru\plugins\superuser.py", line 23, in code    code = ctx.message.content[len(command) + 1:]lightbulb.errors.CommandInvocationError: NameError: name 'command' is not defined"
2020-09-28 16:06:17 [Command Error] User: "Ahnaf#4346", Message: "sh!exec
```py
print()
```", Error: "AttributeError: 'SuperUser' object has no attribute 'eprint'", Traceback: "Traceback (most recent call last):  File "C:\Users\HOME\AppData\Local\Programs\Python\Python38-32\lib\site-packages\lightbulb\command_handler.py", line 852, in process_commands_for_event    await self._invoke_command(command, context, positional_args, keyword_arg)  File "C:\Users\HOME\AppData\Local\Programs\Python\Python38-32\lib\site-packages\lightbulb\command_handler.py", line 788, in _invoke_command    await command.invoke(context)  File "C:\Users\HOME\AppData\Local\Programs\Python\Python38-32\lib\site-packages\lightbulb\commands.py", line 88, in invoke    return await self._callback(instance, context, *new_args, **kwargs)  File "F:\Ahnaf's Folder\Shikamaru Bot\shikamaru\plugins\superuser.py", line 39, in code    "eprint": self.eprint,lightbulb.errors.CommandInvocationError: AttributeError: 'SuperUser' object has no attribute 'eprint'"
2020-09-28 16:08:02 [Command Error] User: "Ahnaf#4346", Message: "sh!exec
```py
print()
```", Error: "NameError: name 'io' is not defined", Traceback: "Traceback (most recent call last):  File "C:\Users\HOME\AppData\Local\Programs\Python\Python38-32\lib\site-packages\lightbulb\command_handler.py", line 852, in process_commands_for_event    await self._invoke_command(command, context, positional_args, keyword_arg)  File "C:\Users\HOME\AppData\Local\Programs\Python\Python38-32\lib\site-packages\lightbulb\command_handler.py", line 788, in _invoke_command    await command.invoke(context)  File "C:\Users\HOME\AppData\Local\Programs\Python\Python38-32\lib\site-packages\lightbulb\commands.py", line 88, in invoke    return await self._callback(instance, context, *new_args, **kwargs)  File "F:\Ahnaf's Folder\Shikamaru Bot\shikamaru\plugins\superuser.py", line 46, in code    stdout = io.StringIO()lightbulb.errors.CommandInvocationError: NameError: name 'io' is not defined"
2020-09-28 16:10:59 [Command Error] User: "Ahnaf#4346", Message: "sh!exec
```py
print()
```", Error: "AttributeError: 'Context' object has no attribute 'send'", Traceback: "Traceback (most recent call last):  File "C:\Users\HOME\AppData\Local\Programs\Python\Python38-32\lib\site-packages\lightbulb\command_handler.py", line 852, in process_commands_for_event    await self._invoke_command(command, context, positional_args, keyword_arg)  File "C:\Users\HOME\AppData\Local\Programs\Python\Python38-32\lib\site-packages\lightbulb\command_handler.py", line 788, in _invoke_command    await command.invoke(context)  File "C:\Users\HOME\AppData\Local\Programs\Python\Python38-32\lib\site-packages\lightbulb\commands.py", line 88, in invoke    return await self._callback(instance, context, *new_args, **kwargs)  File "F:\Ahnaf's Folder\Shikamaru Bot\shikamaru\plugins\superuser.py", line 52, in code    await ctx.send(stdout)lightbulb.errors.CommandInvocationError: AttributeError: 'Context' object has no attribute 'send'"
2020-09-28 16:45:05 [Command Error] User: "Ahnaf#4346", Message: "sh!info", Error: "info", Traceback: "Traceback (most recent call last):  File "C:\Users\HOME\AppData\Local\Programs\Python\Python38-32\lib\site-packages\lightbulb\command_handler.py", line 813, in process_commands_for_event    command = self._validate_command_exists(invoked_with)  File "C:\Users\HOME\AppData\Local\Programs\Python\Python38-32\lib\site-packages\lightbulb\command_handler.py", line 730, in _validate_command_exists    raise errors.CommandNotFound(invoked_with)lightbulb.errors.CommandNotFound: info"
2020-09-28 16:55:23 [Command Error] User: "thomm.o#8637", Message: "sh!ping", Error: "ForbiddenError: Forbidden 403: 'Missing Permissions' for https://discord.com/api/v6/channels/727982024660615198/messages", Traceback: "Traceback (most recent call last):  File "C:\Users\HOME\AppData\Local\Programs\Python\Python38-32\lib\site-packages\lightbulb\command_handler.py", line 852, in process_commands_for_event    await self._invoke_command(command, context, positional_args, keyword_arg)  File "C:\Users\HOME\AppData\Local\Programs\Python\Python38-32\lib\site-packages\lightbulb\command_handler.py", line 788, in _invoke_command    await command.invoke(context)  File "C:\Users\HOME\AppData\Local\Programs\Python\Python38-32\lib\site-packages\lightbulb\commands.py", line 88, in invoke    return await self._callback(instance, context, *new_args, **kwargs)  File "F:\Ahnaf's Folder\Shikamaru Bot\shikamaru\plugins\info.py", line 26, in ping    msg = await ctx.reply("Pinging...")  File "C:\Users\HOME\AppData\Local\Programs\Python\Python38-32\lib\site-packages\lightbulb\context.py", line 193, in reply    return await self.message.reply(*args, **kwargs)  File "C:\Users\HOME\AppData\Local\Programs\Python\Python38-32\lib\site-packages\hikari\messages.py", line 649, in reply    return await self.app.rest.create_message(  File "C:\Users\HOME\AppData\Local\Programs\Python\Python38-32\lib\site-packages\hikari\impl\rest.py", line 1053, in create_message    raw_response = await self._request(route, json=body)  File "C:\Users\HOME\AppData\Local\Programs\Python\Python38-32\lib\site-packages\hikari\impl\rest.py", line 600, in _request    await self._handle_error_response(response)  File "C:\Users\HOME\AppData\Local\Programs\Python\Python38-32\lib\site-packages\hikari\impl\rest.py", line 621, in _handle_error_response    raise await net.generate_error_response(response)lightbulb.errors.CommandInvocationError: ForbiddenError: Forbidden 403: 'Missing Permissions' for https://discord.com/api/v6/channels/727982024660615198/messages"
2020-09-28 20:56:23 [Command Error] User: "Ahnaf#4346", Message: "sh!ping", Error: "ping", Traceback: "Traceback (most recent call last):  File "C:\Users\HOME\AppData\Local\Programs\Python\Python38-32\lib\site-packages\lightbulb\command_handler.py", line 813, in process_commands_for_event    command = self._validate_command_exists(invoked_with)  File "C:\Users\HOME\AppData\Local\Programs\Python\Python38-32\lib\site-packages\lightbulb\command_handler.py", line 730, in _validate_command_exists    raise errors.CommandNotFound(invoked_with)lightbulb.errors.CommandNotFound: ping"
2020-09-28 20:57:43 [Command Error] User: "4 times 1 is even less than 0#3870", Message: "sh!ping", Error: "ping", Traceback: "Traceback (most recent call last):  File "C:\Users\HOME\AppData\Local\Programs\Python\Python38-32\lib\site-packages\lightbulb\command_handler.py", line 813, in process_commands_for_event    command = self._validate_command_exists(invoked_with)  File "C:\Users\HOME\AppData\Local\Programs\Python\Python38-32\lib\site-packages\lightbulb\command_handler.py", line 730, in _validate_command_exists    raise errors.CommandNotFound(invoked_with)lightbulb.errors.CommandNotFound: ping"
2020-09-28 21:05:14 [Command Error] User: "Ahnaf#4346", Message: "sh!help", Error: "TypeError: set_thumbnail() got some positional-only arguments passed as keyword arguments: 'image'", Traceback: "Traceback (most recent call last):  File "C:\Users\HOME\AppData\Local\Programs\Python\Python38-32\lib\site-packages\lightbulb\command_handler.py", line 852, in process_commands_for_event    await self._invoke_command(command, context, positional_args, keyword_arg)  File "C:\Users\HOME\AppData\Local\Programs\Python\Python38-32\lib\site-packages\lightbulb\command_handler.py", line 788, in _invoke_command    await command.invoke(context)  File "C:\Users\HOME\AppData\Local\Programs\Python\Python38-32\lib\site-packages\lightbulb\commands.py", line 495, in invoke    return await self._callback(context, *new_args, **kwargs)  File "C:\Users\HOME\AppData\Local\Programs\Python\Python38-32\lib\site-packages\lightbulb\help.py", line 124, in _help_cmd    await ctx.bot.help_command.resolve_help_obj(ctx, obj)  File "C:\Users\HOME\AppData\Local\Programs\Python\Python38-32\lib\site-packages\lightbulb\help.py", line 175, in resolve_help_obj    await self.send_help_overview(context)  File "F:\Ahnaf's Folder\Shikamaru Bot\shikamaru\plugins\help.py", line 19, in send_help_overview    em.set_thumbnail(image=self.bot.me.avatar_url)lightbulb.errors.CommandInvocationError: TypeError: set_thumbnail() got some positional-only arguments passed as keyword arguments: 'image'"
2020-09-28 21:05:59 [Command Error] User: "Ahnaf#4346", Message: "sh!help", Error: "AttributeError: 'Bot' object has no attribute 'get_groups'", Traceback: "Traceback (most recent call last):  File "C:\Users\HOME\AppData\Local\Programs\Python\Python38-32\lib\site-packages\lightbulb\command_handler.py", line 852, in process_commands_for_event    await self._invoke_command(command, context, positional_args, keyword_arg)  File "C:\Users\HOME\AppData\Local\Programs\Python\Python38-32\lib\site-packages\lightbulb\command_handler.py", line 788, in _invoke_command    await command.invoke(context)  File "C:\Users\HOME\AppData\Local\Programs\Python\Python38-32\lib\site-packages\lightbulb\commands.py", line 495, in invoke    return await self._callback(context, *new_args, **kwargs)  File "C:\Users\HOME\AppData\Local\Programs\Python\Python38-32\lib\site-packages\lightbulb\help.py", line 124, in _help_cmd    await ctx.bot.help_command.resolve_help_obj(ctx, obj)  File "C:\Users\HOME\AppData\Local\Programs\Python\Python38-32\lib\site-packages\lightbulb\help.py", line 175, in resolve_help_obj    await self.send_help_overview(context)  File "F:\Ahnaf's Folder\Shikamaru Bot\shikamaru\plugins\help.py", line 21, in send_help_overview    print(self.bot.get_groups)lightbulb.errors.CommandInvocationError: AttributeError: 'Bot' object has no attribute 'get_groups'"
2020-09-28 21:06:38 [Command Error] User: "Ahnaf#4346", Message: "sh!help", Error: "AttributeError: 'BoundCommand' object has no attribute 'group'", Traceback: "Traceback (most recent call last):  File "C:\Users\HOME\AppData\Local\Programs\Python\Python38-32\lib\site-packages\lightbulb\command_handler.py", line 852, in process_commands_for_event    await self._invoke_command(command, context, positional_args, keyword_arg)  File "C:\Users\HOME\AppData\Local\Programs\Python\Python38-32\lib\site-packages\lightbulb\command_handler.py", line 788, in _invoke_command    await command.invoke(context)  File "C:\Users\HOME\AppData\Local\Programs\Python\Python38-32\lib\site-packages\lightbulb\commands.py", line 495, in invoke    return await self._callback(context, *new_args, **kwargs)  File "C:\Users\HOME\AppData\Local\Programs\Python\Python38-32\lib\site-packages\lightbulb\help.py", line 124, in _help_cmd    await ctx.bot.help_command.resolve_help_obj(ctx, obj)  File "C:\Users\HOME\AppData\Local\Programs\Python\Python38-32\lib\site-packages\lightbulb\help.py", line 175, in resolve_help_obj    await self.send_help_overview(context)  File "F:\Ahnaf's Folder\Shikamaru Bot\shikamaru\plugins\help.py", line 22, in send_help_overview    print(i.group)lightbulb.errors.CommandInvocationError: AttributeError: 'BoundCommand' object has no attribute 'group'"
2020-09-28 21:11:31 [Command Error] User: "Ahnaf#4346", Message: "sh!help", Error: "TypeError: reply() got an unexpected keyword argument 'em'", Traceback: "Traceback (most recent call last):  File "C:\Users\HOME\AppData\Local\Programs\Python\Python38-32\lib\site-packages\lightbulb\command_handler.py", line 852, in process_commands_for_event    await self._invoke_command(command, context, positional_args, keyword_arg)  File "C:\Users\HOME\AppData\Local\Programs\Python\Python38-32\lib\site-packages\lightbulb\command_handler.py", line 788, in _invoke_command    await command.invoke(context)  File "C:\Users\HOME\AppData\Local\Programs\Python\Python38-32\lib\site-packages\lightbulb\commands.py", line 495, in invoke    return await self._callback(context, *new_args, **kwargs)  File "C:\Users\HOME\AppData\Local\Programs\Python\Python38-32\lib\site-packages\lightbulb\help.py", line 124, in _help_cmd    await ctx.bot.help_command.resolve_help_obj(ctx, obj)  File "C:\Users\HOME\AppData\Local\Programs\Python\Python38-32\lib\site-packages\lightbulb\help.py", line 175, in resolve_help_obj    await self.send_help_overview(context)  File "F:\Ahnaf's Folder\Shikamaru Bot\shikamaru\plugins\help.py", line 22, in send_help_overview    await ctx.reply(em=em)  File "C:\Users\HOME\AppData\Local\Programs\Python\Python38-32\lib\site-packages\lightbulb\context.py", line 193, in reply    return await self.message.reply(*args, **kwargs)lightbulb.errors.CommandInvocationError: TypeError: reply() got an unexpected keyword argument 'em'"
2020-09-28 21:14:12 [Command Error] User: "Ahnaf#4346", Message: "sh!help", Error: "AttributeError: 'str' object has no attribute 'commands'", Traceback: "Traceback (most recent call last):  File "C:\Users\HOME\AppData\Local\Programs\Python\Python38-32\lib\site-packages\lightbulb\command_handler.py", line 852, in process_commands_for_event    await self._invoke_command(command, context, positional_args, keyword_arg)  File "C:\Users\HOME\AppData\Local\Programs\Python\Python38-32\lib\site-packages\lightbulb\command_handler.py", line 788, in _invoke_command    await command.invoke(context)  File "C:\Users\HOME\AppData\Local\Programs\Python\Python38-32\lib\site-packages\lightbulb\commands.py", line 495, in invoke    return await self._callback(context, *new_args, **kwargs)  File "C:\Users\HOME\AppData\Local\Programs\Python\Python38-32\lib\site-packages\lightbulb\help.py", line 124, in _help_cmd    await ctx.bot.help_command.resolve_help_obj(ctx, obj)  File "C:\Users\HOME\AppData\Local\Programs\Python\Python38-32\lib\site-packages\lightbulb\help.py", line 175, in resolve_help_obj    await self.send_help_overview(context)  File "F:\Ahnaf's Folder\Shikamaru Bot\shikamaru\plugins\help.py", line 21, in send_help_overview    em.add_field(name=str(plugin), value=f"{f'`cmd.name`, ' for cmd in plugin.commands}")lightbulb.errors.CommandInvocationError: AttributeError: 'str' object has no attribute 'commands'"
2020-09-28 21:19:18 [Command Error] User: "Ahnaf#4346", Message: "sh!help", Error: "TypeError: in embed.fields[0].value - cannot have empty string", Traceback: "Traceback (most recent call last):  File "C:\Users\HOME\AppData\Local\Programs\Python\Python38-32\lib\site-packages\lightbulb\command_handler.py", line 852, in process_commands_for_event    await self._invoke_command(command, context, positional_args, keyword_arg)  File "C:\Users\HOME\AppData\Local\Programs\Python\Python38-32\lib\site-packages\lightbulb\command_handler.py", line 788, in _invoke_command    await command.invoke(context)  File "C:\Users\HOME\AppData\Local\Programs\Python\Python38-32\lib\site-packages\lightbulb\commands.py", line 495, in invoke    return await self._callback(context, *new_args, **kwargs)  File "C:\Users\HOME\AppData\Local\Programs\Python\Python38-32\lib\site-packages\lightbulb\help.py", line 124, in _help_cmd    await ctx.bot.help_command.resolve_help_obj(ctx, obj)  File "C:\Users\HOME\AppData\Local\Programs\Python\Python38-32\lib\site-packages\lightbulb\help.py", line 175, in resolve_help_obj    await self.send_help_overview(context)  File "F:\Ahnaf's Folder\Shikamaru Bot\shikamaru\plugins\help.py", line 24, in send_help_overview    await ctx.reply(embed=em)  File "C:\Users\HOME\AppData\Local\Programs\Python\Python38-32\lib\site-packages\lightbulb\context.py", line 193, in reply    return await self.message.reply(*args, **kwargs)  File "C:\Users\HOME\AppData\Local\Programs\Python\Python38-32\lib\site-packages\hikari\messages.py", line 649, in reply    return await self.app.rest.create_message(  File "C:\Users\HOME\AppData\Local\Programs\Python\Python38-32\lib\site-packages\hikari\impl\rest.py", line 1034, in create_message    embed_payload, embed_attachments = self._entity_factory.serialize_embed(embed)  File "C:\Users\HOME\AppData\Local\Programs\Python\Python38-32\lib\site-packages\hikari\impl\entity_factory.py", line 888, in serialize_embed    raise TypeError(f"in embed.fields[{i}].value - cannot have empty string")lightbulb.errors.CommandInvocationError: TypeError: in embed.fields[0].value - cannot have empty string"
2020-09-28 21:27:43 [Command Error] User: "Ahnaf#4346", Message: "sh!help", Error: "TypeError: in embed.fields[0].value - cannot have empty string", Traceback: "Traceback (most recent call last):  File "C:\Users\HOME\AppData\Local\Programs\Python\Python38-32\lib\site-packages\lightbulb\command_handler.py", line 852, in process_commands_for_event    await self._invoke_command(command, context, positional_args, keyword_arg)  File "C:\Users\HOME\AppData\Local\Programs\Python\Python38-32\lib\site-packages\lightbulb\command_handler.py", line 788, in _invoke_command    await command.invoke(context)  File "C:\Users\HOME\AppData\Local\Programs\Python\Python38-32\lib\site-packages\lightbulb\commands.py", line 495, in invoke    return await self._callback(context, *new_args, **kwargs)  File "C:\Users\HOME\AppData\Local\Programs\Python\Python38-32\lib\site-packages\lightbulb\help.py", line 124, in _help_cmd    await ctx.bot.help_command.resolve_help_obj(ctx, obj)  File "C:\Users\HOME\AppData\Local\Programs\Python\Python38-32\lib\site-packages\lightbulb\help.py", line 175, in resolve_help_obj    await self.send_help_overview(context)  File "F:\Ahnaf's Folder\Shikamaru Bot\shikamaru\plugins\help.py", line 30, in send_help_overview    await ctx.reply(embed=em)  File "C:\Users\HOME\AppData\Local\Programs\Python\Python38-32\lib\site-packages\lightbulb\context.py", line 193, in reply    return await self.message.reply(*args, **kwargs)  File "C:\Users\HOME\AppData\Local\Programs\Python\Python38-32\lib\site-packages\hikari\messages.py", line 649, in reply    return await self.app.rest.create_message(  File "C:\Users\HOME\AppData\Local\Programs\Python\Python38-32\lib\site-packages\hikari\impl\rest.py", line 1034, in create_message    embed_payload, embed_attachments = self._entity_factory.serialize_embed(embed)  File "C:\Users\HOME\AppData\Local\Programs\Python\Python38-32\lib\site-packages\hikari\impl\entity_factory.py", line 888, in serialize_embed    raise TypeError(f"in embed.fields[{i}].value - cannot have empty string")lightbulb.errors.CommandInvocationError: TypeError: in embed.fields[0].value - cannot have empty string"
2020-09-28 21:45:11 [Command Error] User: "Ahnaf#4346", Message: "sh!help", Error: "TypeError: in embed.fields[0].value - cannot have empty string", Traceback: "Traceback (most recent call last):  File "C:\Users\HOME\AppData\Local\Programs\Python\Python38-32\lib\site-packages\lightbulb\command_handler.py", line 852, in process_commands_for_event    await self._invoke_command(command, context, positional_args, keyword_arg)  File "C:\Users\HOME\AppData\Local\Programs\Python\Python38-32\lib\site-packages\lightbulb\command_handler.py", line 788, in _invoke_command    await command.invoke(context)  File "C:\Users\HOME\AppData\Local\Programs\Python\Python38-32\lib\site-packages\lightbulb\commands.py", line 495, in invoke    return await self._callback(context, *new_args, **kwargs)  File "C:\Users\HOME\AppData\Local\Programs\Python\Python38-32\lib\site-packages\lightbulb\help.py", line 124, in _help_cmd    await ctx.bot.help_command.resolve_help_obj(ctx, obj)  File "C:\Users\HOME\AppData\Local\Programs\Python\Python38-32\lib\site-packages\lightbulb\help.py", line 175, in resolve_help_obj    await self.send_help_overview(context)  File "F:\Ahnaf's Folder\Shikamaru Bot\shikamaru\plugins\help.py", line 30, in send_help_overview    await ctx.reply(embed=em)  File "C:\Users\HOME\AppData\Local\Programs\Python\Python38-32\lib\site-packages\lightbulb\context.py", line 193, in reply    return await self.message.reply(*args, **kwargs)  File "C:\Users\HOME\AppData\Local\Programs\Python\Python38-32\lib\site-packages\hikari\messages.py", line 649, in reply    return await self.app.rest.create_message(  File "C:\Users\HOME\AppData\Local\Programs\Python\Python38-32\lib\site-packages\hikari\impl\rest.py", line 1034, in create_message    embed_payload, embed_attachments = self._entity_factory.serialize_embed(embed)  File "C:\Users\HOME\AppData\Local\Programs\Python\Python38-32\lib\site-packages\hikari\impl\entity_factory.py", line 888, in serialize_embed    raise TypeError(f"in embed.fields[{i}].value - cannot have empty string")lightbulb.errors.CommandInvocationError: TypeError: in embed.fields[0].value - cannot have empty string"
2020-09-28 21:45:47 [Command Error] User: "Ahnaf#4346", Message: "sh!help", Error: "TypeError: in embed.fields[0].value - cannot have empty string", Traceback: "Traceback (most recent call last):  File "C:\Users\HOME\AppData\Local\Programs\Python\Python38-32\lib\site-packages\lightbulb\command_handler.py", line 852, in process_commands_for_event    await self._invoke_command(command, context, positional_args, keyword_arg)  File "C:\Users\HOME\AppData\Local\Programs\Python\Python38-32\lib\site-packages\lightbulb\command_handler.py", line 788, in _invoke_command    await command.invoke(context)  File "C:\Users\HOME\AppData\Local\Programs\Python\Python38-32\lib\site-packages\lightbulb\commands.py", line 495, in invoke    return await self._callback(context, *new_args, **kwargs)  File "C:\Users\HOME\AppData\Local\Programs\Python\Python38-32\lib\site-packages\lightbulb\help.py", line 124, in _help_cmd    await ctx.bot.help_command.resolve_help_obj(ctx, obj)  File "C:\Users\HOME\AppData\Local\Programs\Python\Python38-32\lib\site-packages\lightbulb\help.py", line 175, in resolve_help_obj    await self.send_help_overview(context)  File "F:\Ahnaf's Folder\Shikamaru Bot\shikamaru\plugins\help.py", line 30, in send_help_overview    await ctx.reply(embed=em)  File "C:\Users\HOME\AppData\Local\Programs\Python\Python38-32\lib\site-packages\lightbulb\context.py", line 193, in reply    return await self.message.reply(*args, **kwargs)  File "C:\Users\HOME\AppData\Local\Programs\Python\Python38-32\lib\site-packages\hikari\messages.py", line 649, in reply    return await self.app.rest.create_message(  File "C:\Users\HOME\AppData\Local\Programs\Python\Python38-32\lib\site-packages\hikari\impl\rest.py", line 1034, in create_message    embed_payload, embed_attachments = self._entity_factory.serialize_embed(embed)  File "C:\Users\HOME\AppData\Local\Programs\Python\Python38-32\lib\site-packages\hikari\impl\entity_factory.py", line 888, in serialize_embed    raise TypeError(f"in embed.fields[{i}].value - cannot have empty string")lightbulb.errors.CommandInvocationError: TypeError: in embed.fields[0].value - cannot have empty string"
2020-09-28 21:46:52 [Command Error] User: "Ahnaf#4346", Message: "sh!help", Error: "TypeError: in embed.fields[0].value - cannot have empty string", Traceback: "Traceback (most recent call last):  File "C:\Users\HOME\AppData\Local\Programs\Python\Python38-32\lib\site-packages\lightbulb\command_handler.py", line 852, in process_commands_for_event    await self._invoke_command(command, context, positional_args, keyword_arg)  File "C:\Users\HOME\AppData\Local\Programs\Python\Python38-32\lib\site-packages\lightbulb\command_handler.py", line 788, in _invoke_command    await command.invoke(context)  File "C:\Users\HOME\AppData\Local\Programs\Python\Python38-32\lib\site-packages\lightbulb\commands.py", line 495, in invoke    return await self._callback(context, *new_args, **kwargs)  File "C:\Users\HOME\AppData\Local\Programs\Python\Python38-32\lib\site-packages\lightbulb\help.py", line 124, in _help_cmd    await ctx.bot.help_command.resolve_help_obj(ctx, obj)  File "C:\Users\HOME\AppData\Local\Programs\Python\Python38-32\lib\site-packages\lightbulb\help.py", line 175, in resolve_help_obj    await self.send_help_overview(context)  File "F:\Ahnaf's Folder\Shikamaru Bot\shikamaru\plugins\help.py", line 30, in send_help_overview    await ctx.reply(embed=em)  File "C:\Users\HOME\AppData\Local\Programs\Python\Python38-32\lib\site-packages\lightbulb\context.py", line 193, in reply    return await self.message.reply(*args, **kwargs)  File "C:\Users\HOME\AppData\Local\Programs\Python\Python38-32\lib\site-packages\hikari\messages.py", line 649, in reply    return await self.app.rest.create_message(  File "C:\Users\HOME\AppData\Local\Programs\Python\Python38-32\lib\site-packages\hikari\impl\rest.py", line 1034, in create_message    embed_payload, embed_attachments = self._entity_factory.serialize_embed(embed)  File "C:\Users\HOME\AppData\Local\Programs\Python\Python38-32\lib\site-packages\hikari\impl\entity_factory.py", line 888, in serialize_embed    raise TypeError(f"in embed.fields[{i}].value - cannot have empty string")lightbulb.errors.CommandInvocationError: TypeError: in embed.fields[0].value - cannot have empty string"
2020-09-28 21:47:54 [Command Error] User: "Ahnaf#4346", Message: "sh!help", Error: "TypeError: in embed.fields[0].value - cannot have empty string", Traceback: "Traceback (most recent call last):  File "C:\Users\HOME\AppData\Local\Programs\Python\Python38-32\lib\site-packages\lightbulb\command_handler.py", line 852, in process_commands_for_event    await self._invoke_command(command, context, positional_args, keyword_arg)  File "C:\Users\HOME\AppData\Local\Programs\Python\Python38-32\lib\site-packages\lightbulb\command_handler.py", line 788, in _invoke_command    await command.invoke(context)  File "C:\Users\HOME\AppData\Local\Programs\Python\Python38-32\lib\site-packages\lightbulb\commands.py", line 495, in invoke    return await self._callback(context, *new_args, **kwargs)  File "C:\Users\HOME\AppData\Local\Programs\Python\Python38-32\lib\site-packages\lightbulb\help.py", line 124, in _help_cmd    await ctx.bot.help_command.resolve_help_obj(ctx, obj)  File "C:\Users\HOME\AppData\Local\Programs\Python\Python38-32\lib\site-packages\lightbulb\help.py", line 175, in resolve_help_obj    await self.send_help_overview(context)  File "F:\Ahnaf's Folder\Shikamaru Bot\shikamaru\plugins\help.py", line 30, in send_help_overview    await ctx.reply(embed=em)  File "C:\Users\HOME\AppData\Local\Programs\Python\Python38-32\lib\site-packages\lightbulb\context.py", line 193, in reply    return await self.message.reply(*args, **kwargs)  File "C:\Users\HOME\AppData\Local\Programs\Python\Python38-32\lib\site-packages\hikari\messages.py", line 649, in reply    return await self.app.rest.create_message(  File "C:\Users\HOME\AppData\Local\Programs\Python\Python38-32\lib\site-packages\hikari\impl\rest.py", line 1034, in create_message    embed_payload, embed_attachments = self._entity_factory.serialize_embed(embed)  File "C:\Users\HOME\AppData\Local\Programs\Python\Python38-32\lib\site-packages\hikari\impl\entity_factory.py", line 888, in serialize_embed    raise TypeError(f"in embed.fields[{i}].value - cannot have empty string")lightbulb.errors.CommandInvocationError: TypeError: in embed.fields[0].value - cannot have empty string"
2020-09-28 21:48:56 [Command Error] User: "Ahnaf#4346", Message: "sh!help", Error: "TypeError: in embed.fields[0].value - cannot have empty string", Traceback: "Traceback (most recent call last):  File "C:\Users\HOME\AppData\Local\Programs\Python\Python38-32\lib\site-packages\lightbulb\command_handler.py", line 852, in process_commands_for_event    await self._invoke_command(command, context, positional_args, keyword_arg)  File "C:\Users\HOME\AppData\Local\Programs\Python\Python38-32\lib\site-packages\lightbulb\command_handler.py", line 788, in _invoke_command    await command.invoke(context)  File "C:\Users\HOME\AppData\Local\Programs\Python\Python38-32\lib\site-packages\lightbulb\commands.py", line 495, in invoke    return await self._callback(context, *new_args, **kwargs)  File "C:\Users\HOME\AppData\Local\Programs\Python\Python38-32\lib\site-packages\lightbulb\help.py", line 124, in _help_cmd    await ctx.bot.help_command.resolve_help_obj(ctx, obj)  File "C:\Users\HOME\AppData\Local\Programs\Python\Python38-32\lib\site-packages\lightbulb\help.py", line 175, in resolve_help_obj    await self.send_help_overview(context)  File "F:\Ahnaf's Folder\Shikamaru Bot\shikamaru\plugins\help.py", line 31, in send_help_overview    await ctx.reply(embed=em)  File "C:\Users\HOME\AppData\Local\Programs\Python\Python38-32\lib\site-packages\lightbulb\context.py", line 193, in reply    return await self.message.reply(*args, **kwargs)  File "C:\Users\HOME\AppData\Local\Programs\Python\Python38-32\lib\site-packages\hikari\messages.py", line 649, in reply    return await self.app.rest.create_message(  File "C:\Users\HOME\AppData\Local\Programs\Python\Python38-32\lib\site-packages\hikari\impl\rest.py", line 1034, in create_message    embed_payload, embed_attachments = self._entity_factory.serialize_embed(embed)  File "C:\Users\HOME\AppData\Local\Programs\Python\Python38-32\lib\site-packages\hikari\impl\entity_factory.py", line 888, in serialize_embed    raise TypeError(f"in embed.fields[{i}].value - cannot have empty string")lightbulb.errors.CommandInvocationError: TypeError: in embed.fields[0].value - cannot have empty string"
2020-09-28 21:51:20 [Command Error] User: "Ahnaf#4346", Message: "sh!help", Error: "TypeError: in embed.fields[1].value - cannot have empty string", Traceback: "Traceback (most recent call last):  File "C:\Users\HOME\AppData\Local\Programs\Python\Python38-32\lib\site-packages\lightbulb\command_handler.py", line 852, in process_commands_for_event    await self._invoke_command(command, context, positional_args, keyword_arg)  File "C:\Users\HOME\AppData\Local\Programs\Python\Python38-32\lib\site-packages\lightbulb\command_handler.py", line 788, in _invoke_command    await command.invoke(context)  File "C:\Users\HOME\AppData\Local\Programs\Python\Python38-32\lib\site-packages\lightbulb\commands.py", line 495, in invoke    return await self._callback(context, *new_args, **kwargs)  File "C:\Users\HOME\AppData\Local\Programs\Python\Python38-32\lib\site-packages\lightbulb\help.py", line 124, in _help_cmd    await ctx.bot.help_command.resolve_help_obj(ctx, obj)  File "C:\Users\HOME\AppData\Local\Programs\Python\Python38-32\lib\site-packages\lightbulb\help.py", line 175, in resolve_help_obj    await self.send_help_overview(context)  File "F:\Ahnaf's Folder\Shikamaru Bot\shikamaru\plugins\help.py", line 33, in send_help_overview    await ctx.reply(embed=em)  File "C:\Users\HOME\AppData\Local\Programs\Python\Python38-32\lib\site-packages\lightbulb\context.py", line 193, in reply    return await self.message.reply(*args, **kwargs)  File "C:\Users\HOME\AppData\Local\Programs\Python\Python38-32\lib\site-packages\hikari\messages.py", line 649, in reply    return await self.app.rest.create_message(  File "C:\Users\HOME\AppData\Local\Programs\Python\Python38-32\lib\site-packages\hikari\impl\rest.py", line 1034, in create_message    embed_payload, embed_attachments = self._entity_factory.serialize_embed(embed)  File "C:\Users\HOME\AppData\Local\Programs\Python\Python38-32\lib\site-packages\hikari\impl\entity_factory.py", line 888, in serialize_embed    raise TypeError(f"in embed.fields[{i}].value - cannot have empty string")lightbulb.errors.CommandInvocationError: TypeError: in embed.fields[1].value - cannot have empty string"
2020-09-28 21:51:57 [Command Error] User: "Ahnaf#4346", Message: "sh!help", Error: "TypeError: in embed.fields[1].value - cannot have empty string", Traceback: "Traceback (most recent call last):  File "C:\Users\HOME\AppData\Local\Programs\Python\Python38-32\lib\site-packages\lightbulb\command_handler.py", line 852, in process_commands_for_event    await self._invoke_command(command, context, positional_args, keyword_arg)  File "C:\Users\HOME\AppData\Local\Programs\Python\Python38-32\lib\site-packages\lightbulb\command_handler.py", line 788, in _invoke_command    await command.invoke(context)  File "C:\Users\HOME\AppData\Local\Programs\Python\Python38-32\lib\site-packages\lightbulb\commands.py", line 495, in invoke    return await self._callback(context, *new_args, **kwargs)  File "C:\Users\HOME\AppData\Local\Programs\Python\Python38-32\lib\site-packages\lightbulb\help.py", line 124, in _help_cmd    await ctx.bot.help_command.resolve_help_obj(ctx, obj)  File "C:\Users\HOME\AppData\Local\Programs\Python\Python38-32\lib\site-packages\lightbulb\help.py", line 175, in resolve_help_obj    await self.send_help_overview(context)  File "F:\Ahnaf's Folder\Shikamaru Bot\shikamaru\plugins\help.py", line 33, in send_help_overview    await ctx.reply(embed=em)  File "C:\Users\HOME\AppData\Local\Programs\Python\Python38-32\lib\site-packages\lightbulb\context.py", line 193, in reply    return await self.message.reply(*args, **kwargs)  File "C:\Users\HOME\AppData\Local\Programs\Python\Python38-32\lib\site-packages\hikari\messages.py", line 649, in reply    return await self.app.rest.create_message(  File "C:\Users\HOME\AppData\Local\Programs\Python\Python38-32\lib\site-packages\hikari\impl\rest.py", line 1034, in create_message    embed_payload, embed_attachments = self._entity_factory.serialize_embed(embed)  File "C:\Users\HOME\AppData\Local\Programs\Python\Python38-32\lib\site-packages\hikari\impl\entity_factory.py", line 888, in serialize_embed    raise TypeError(f"in embed.fields[{i}].value - cannot have empty string")lightbulb.errors.CommandInvocationError: TypeError: in embed.fields[1].value - cannot have empty string"
2020-09-28 21:53:56 [Command Error] User: "Ahnaf#4346", Message: "sh!help", Error: "TypeError: in embed.fields[1].value - cannot have empty string", Traceback: "Traceback (most recent call last):  File "C:\Users\HOME\AppData\Local\Programs\Python\Python38-32\lib\site-packages\lightbulb\command_handler.py", line 852, in process_commands_for_event    await self._invoke_command(command, context, positional_args, keyword_arg)  File "C:\Users\HOME\AppData\Local\Programs\Python\Python38-32\lib\site-packages\lightbulb\command_handler.py", line 788, in _invoke_command    await command.invoke(context)  File "C:\Users\HOME\AppData\Local\Programs\Python\Python38-32\lib\site-packages\lightbulb\commands.py", line 495, in invoke    return await self._callback(context, *new_args, **kwargs)  File "C:\Users\HOME\AppData\Local\Programs\Python\Python38-32\lib\site-packages\lightbulb\help.py", line 124, in _help_cmd    await ctx.bot.help_command.resolve_help_obj(ctx, obj)  File "C:\Users\HOME\AppData\Local\Programs\Python\Python38-32\lib\site-packages\lightbulb\help.py", line 175, in resolve_help_obj    await self.send_help_overview(context)  File "F:\Ahnaf's Folder\Shikamaru Bot\shikamaru\plugins\help.py", line 33, in send_help_overview    await ctx.reply(embed=em)  File "C:\Users\HOME\AppData\Local\Programs\Python\Python38-32\lib\site-packages\lightbulb\context.py", line 193, in reply    return await self.message.reply(*args, **kwargs)  File "C:\Users\HOME\AppData\Local\Programs\Python\Python38-32\lib\site-packages\hikari\messages.py", line 649, in reply    return await self.app.rest.create_message(  File "C:\Users\HOME\AppData\Local\Programs\Python\Python38-32\lib\site-packages\hikari\impl\rest.py", line 1034, in create_message    embed_payload, embed_attachments = self._entity_factory.serialize_embed(embed)  File "C:\Users\HOME\AppData\Local\Programs\Python\Python38-32\lib\site-packages\hikari\impl\entity_factory.py", line 888, in serialize_embed    raise TypeError(f"in embed.fields[{i}].value - cannot have empty string")lightbulb.errors.CommandInvocationError: TypeError: in embed.fields[1].value - cannot have empty string"
2020-09-28 21:55:26 [Command Error] User: "Ahnaf#4346", Message: "sh!help", Error: "BadRequestError: Bad Request 400: 'Cannot send an empty message' for https://discord.com/api/v6/channels/715942542864154728/messages", Traceback: "Traceback (most recent call last):  File "C:\Users\HOME\AppData\Local\Programs\Python\Python38-32\lib\site-packages\lightbulb\command_handler.py", line 852, in process_commands_for_event    await self._invoke_command(command, context, positional_args, keyword_arg)  File "C:\Users\HOME\AppData\Local\Programs\Python\Python38-32\lib\site-packages\lightbulb\command_handler.py", line 788, in _invoke_command    await command.invoke(context)  File "C:\Users\HOME\AppData\Local\Programs\Python\Python38-32\lib\site-packages\lightbulb\commands.py", line 495, in invoke    return await self._callback(context, *new_args, **kwargs)  File "C:\Users\HOME\AppData\Local\Programs\Python\Python38-32\lib\site-packages\lightbulb\help.py", line 124, in _help_cmd    await ctx.bot.help_command.resolve_help_obj(ctx, obj)  File "C:\Users\HOME\AppData\Local\Programs\Python\Python38-32\lib\site-packages\lightbulb\help.py", line 175, in resolve_help_obj    await self.send_help_overview(context)  File "F:\Ahnaf's Folder\Shikamaru Bot\shikamaru\plugins\help.py", line 30, in send_help_overview    await ctx.reply(string)  File "C:\Users\HOME\AppData\Local\Programs\Python\Python38-32\lib\site-packages\lightbulb\context.py", line 193, in reply    return await self.message.reply(*args, **kwargs)  File "C:\Users\HOME\AppData\Local\Programs\Python\Python38-32\lib\site-packages\hikari\messages.py", line 649, in reply    return await self.app.rest.create_message(  File "C:\Users\HOME\AppData\Local\Programs\Python\Python38-32\lib\site-packages\hikari\impl\rest.py", line 1053, in create_message    raw_response = await self._request(route, json=body)  File "C:\Users\HOME\AppData\Local\Programs\Python\Python38-32\lib\site-packages\hikari\impl\rest.py", line 600, in _request    await self._handle_error_response(response)  File "C:\Users\HOME\AppData\Local\Programs\Python\Python38-32\lib\site-packages\hikari\impl\rest.py", line 621, in _handle_error_response    raise await net.generate_error_response(response)lightbulb.errors.CommandInvocationError: BadRequestError: Bad Request 400: 'Cannot send an empty message' for https://discord.com/api/v6/channels/715942542864154728/messages"
2020-09-28 21:56:48 [Command Error] User: "Ahnaf#4346", Message: "sh!help", Error: "BadRequestError: Bad Request 400: 'Cannot send an empty message' for https://discord.com/api/v6/channels/715942542864154728/messages", Traceback: "Traceback (most recent call last):  File "C:\Users\HOME\AppData\Local\Programs\Python\Python38-32\lib\site-packages\lightbulb\command_handler.py", line 852, in process_commands_for_event    await self._invoke_command(command, context, positional_args, keyword_arg)  File "C:\Users\HOME\AppData\Local\Programs\Python\Python38-32\lib\site-packages\lightbulb\command_handler.py", line 788, in _invoke_command    await command.invoke(context)  File "C:\Users\HOME\AppData\Local\Programs\Python\Python38-32\lib\site-packages\lightbulb\commands.py", line 495, in invoke    return await self._callback(context, *new_args, **kwargs)  File "C:\Users\HOME\AppData\Local\Programs\Python\Python38-32\lib\site-packages\lightbulb\help.py", line 124, in _help_cmd    await ctx.bot.help_command.resolve_help_obj(ctx, obj)  File "C:\Users\HOME\AppData\Local\Programs\Python\Python38-32\lib\site-packages\lightbulb\help.py", line 175, in resolve_help_obj    await self.send_help_overview(context)  File "F:\Ahnaf's Folder\Shikamaru Bot\shikamaru\plugins\help.py", line 31, in send_help_overview    await ctx.reply(string)  File "C:\Users\HOME\AppData\Local\Programs\Python\Python38-32\lib\site-packages\lightbulb\context.py", line 193, in reply    return await self.message.reply(*args, **kwargs)  File "C:\Users\HOME\AppData\Local\Programs\Python\Python38-32\lib\site-packages\hikari\messages.py", line 649, in reply    return await self.app.rest.create_message(  File "C:\Users\HOME\AppData\Local\Programs\Python\Python38-32\lib\site-packages\hikari\impl\rest.py", line 1053, in create_message    raw_response = await self._request(route, json=body)  File "C:\Users\HOME\AppData\Local\Programs\Python\Python38-32\lib\site-packages\hikari\impl\rest.py", line 600, in _request    await self._handle_error_response(response)  File "C:\Users\HOME\AppData\Local\Programs\Python\Python38-32\lib\site-packages\hikari\impl\rest.py", line 621, in _handle_error_response    raise await net.generate_error_response(response)lightbulb.errors.CommandInvocationError: BadRequestError: Bad Request 400: 'Cannot send an empty message' for https://discord.com/api/v6/channels/715942542864154728/messages"
2020-09-28 22:14:56 [Command Error] User: "Ahnaf#4346", Message: "sh!help dasdsdasdsa", Error: "TypeError: reply() takes from 1 to 2 positional arguments but 3 were given", Traceback: "Traceback (most recent call last):  File "C:\Users\HOME\AppData\Local\Programs\Python\Python38-32\lib\site-packages\lightbulb\command_handler.py", line 852, in process_commands_for_event    await self._invoke_command(command, context, positional_args, keyword_arg)  File "C:\Users\HOME\AppData\Local\Programs\Python\Python38-32\lib\site-packages\lightbulb\command_handler.py", line 788, in _invoke_command    await command.invoke(context)  File "C:\Users\HOME\AppData\Local\Programs\Python\Python38-32\lib\site-packages\lightbulb\commands.py", line 495, in invoke    return await self._callback(context, *new_args, **kwargs)  File "C:\Users\HOME\AppData\Local\Programs\Python\Python38-32\lib\site-packages\lightbulb\help.py", line 124, in _help_cmd    await ctx.bot.help_command.resolve_help_obj(ctx, obj)  File "C:\Users\HOME\AppData\Local\Programs\Python\Python38-32\lib\site-packages\lightbulb\help.py", line 187, in resolve_help_obj    await self.object_not_found(context, obj[0])  File "F:\Ahnaf's Folder\Shikamaru Bot\shikamaru\plugins\help.py", line 14, in object_not_found    await ctx.reply("Command/Category not found for", name)  File "C:\Users\HOME\AppData\Local\Programs\Python\Python38-32\lib\site-packages\lightbulb\context.py", line 193, in reply    return await self.message.reply(*args, **kwargs)lightbulb.errors.CommandInvocationError: TypeError: reply() takes from 1 to 2 positional arguments but 3 were given"
