2020-09-28 13:41:35 [Command Error] User: "Ahnaf#4346", Message: "sh!wrong", Error: "ZeroDivisionError: division by zero", Traceback: "Traceback (most recent call last):  File "C:\Users\HOME\AppData\Local\Programs\Python\Python38-32\lib\site-packages\lightbulb\command_handler.py", line 852, in process_commands_for_event    await self._invoke_command(command, context, positional_args, keyword_arg)  File "C:\Users\HOME\AppData\Local\Programs\Python\Python38-32\lib\site-packages\lightbulb\command_handler.py", line 788, in _invoke_command    await command.invoke(context)  File "C:\Users\HOME\AppData\Local\Programs\Python\Python38-32\lib\site-packages\lightbulb\commands.py", line 495, in invoke    return await self._callback(context, *new_args, **kwargs)  File "F:\Ahnaf's Folder\Shikamaru Bot\shikamaru\bot.py", line 20, in wrong    await ctx.reply(1/0)lightbulb.errors.CommandInvocationError: ZeroDivisionError: division by zero"
2020-09-28 14:59:13 [Command Error] User: "Ahnaf#4346", Message: "sh!github", Error: "github", Traceback: "Traceback (most recent call last):  File "C:\Users\HOME\AppData\Local\Programs\Python\Python38-32\lib\site-packages\lightbulb\command_handler.py", line 840, in process_commands_for_event    positional_args, keyword_arg = self.resolve_args_for_command(command, final_args)  File "C:\Users\HOME\AppData\Local\Programs\Python\Python38-32\lib\site-packages\lightbulb\command_handler.py", line 768, in resolve_args_for_command    raise errors.NotEnoughArguments(command.name)lightbulb.errors.NotEnoughArguments: github"
2020-09-28 15:01:00 [Command Error] User: "Ahnaf#4346", Message: "sh!help github", Error: "AttributeError: 'str' object has no attribute 'annotation'", Traceback: "Traceback (most recent call last):  File "C:\Users\HOME\AppData\Local\Programs\Python\Python38-32\lib\site-packages\lightbulb\command_handler.py", line 852, in process_commands_for_event    await self._invoke_command(command, context, positional_args, keyword_arg)  File "C:\Users\HOME\AppData\Local\Programs\Python\Python38-32\lib\site-packages\lightbulb\command_handler.py", line 788, in _invoke_command    await command.invoke(context)  File "C:\Users\HOME\AppData\Local\Programs\Python\Python38-32\lib\site-packages\lightbulb\commands.py", line 495, in invoke    return await self._callback(context, *new_args, **kwargs)  File "C:\Users\HOME\AppData\Local\Programs\Python\Python38-32\lib\site-packages\lightbulb\help.py", line 124, in _help_cmd    await ctx.bot.help_command.resolve_help_obj(ctx, obj)  File "C:\Users\HOME\AppData\Local\Programs\Python\Python38-32\lib\site-packages\lightbulb\help.py", line 181, in resolve_help_obj    await self.send_command_help(context, command)  File "F:\Ahnaf's Folder\Shikamaru Bot\shikamaru\plugins\help.py", line 23, in send_command_help    print([i.annotation.__name__ for i in command.arg_details.args])  File "F:\Ahnaf's Folder\Shikamaru Bot\shikamaru\plugins\help.py", line 23, in <listcomp>    print([i.annotation.__name__ for i in command.arg_details.args])lightbulb.errors.CommandInvocationError: AttributeError: 'str' object has no attribute 'annotation'"
2020-09-28 15:31:18 [Command Error] User: "Ahnaf#4346", Message: "sh!help github", Error: "TypeError: __init__() got an unexpected keyword argument 'name'", Traceback: "Traceback (most recent call last):  File "C:\Users\HOME\AppData\Local\Programs\Python\Python38-32\lib\site-packages\lightbulb\command_handler.py", line 852, in process_commands_for_event    await self._invoke_command(command, context, positional_args, keyword_arg)  File "C:\Users\HOME\AppData\Local\Programs\Python\Python38-32\lib\site-packages\lightbulb\command_handler.py", line 788, in _invoke_command    await command.invoke(context)  File "C:\Users\HOME\AppData\Local\Programs\Python\Python38-32\lib\site-packages\lightbulb\commands.py", line 495, in invoke    return await self._callback(context, *new_args, **kwargs)  File "C:\Users\HOME\AppData\Local\Programs\Python\Python38-32\lib\site-packages\lightbulb\help.py", line 124, in _help_cmd    await ctx.bot.help_command.resolve_help_obj(ctx, obj)  File "C:\Users\HOME\AppData\Local\Programs\Python\Python38-32\lib\site-packages\lightbulb\help.py", line 181, in resolve_help_obj    await self.send_command_help(context, command)  File "F:\Ahnaf's Folder\Shikamaru Bot\shikamaru\plugins\help.py", line 23, in send_command_help    em = hikari.Embed(name=f"Help for: {command.name.capitalize()}", color="#ae00ff" )lightbulb.errors.CommandInvocationError: TypeError: __init__() got an unexpected keyword argument 'name'"
2020-09-28 15:32:22 [Command Error] User: "Forbidden#0001", Message: "sh!github", Error: "github", Traceback: "Traceback (most recent call last):  File "C:\Users\HOME\AppData\Local\Programs\Python\Python38-32\lib\site-packages\lightbulb\command_handler.py", line 840, in process_commands_for_event    positional_args, keyword_arg = self.resolve_args_for_command(command, final_args)  File "C:\Users\HOME\AppData\Local\Programs\Python\Python38-32\lib\site-packages\lightbulb\command_handler.py", line 768, in resolve_args_for_command    raise errors.NotEnoughArguments(command.name)lightbulb.errors.NotEnoughArguments: github"
2020-09-28 15:47:40 [Command Error] User: "Ahnaf#4346", Message: "sh!exec
```py
print("Oof")
```", Error: "You are not the owner of this bot", Traceback: "Traceback (most recent call last):  File "C:\Users\HOME\AppData\Local\Programs\Python\Python38-32\lib\site-packages\lightbulb\command_handler.py", line 841, in process_commands_for_event    await self._evaluate_checks(command, context)  File "C:\Users\HOME\AppData\Local\Programs\Python\Python38-32\lib\site-packages\lightbulb\command_handler.py", line 685, in _evaluate_checks    raise failed_checks[0]  File "C:\Users\HOME\AppData\Local\Programs\Python\Python38-32\lib\site-packages\lightbulb\command_handler.py", line 673, in _evaluate_checks    if not await check(context):  File "C:\Users\HOME\AppData\Local\Programs\Python\Python38-32\lib\site-packages\lightbulb\checks.py", line 93, in _owner_only    raise errors.NotOwner("You are not the owner of this bot")lightbulb.errors.NotOwner: You are not the owner of this bot"
2020-09-28 15:50:10 [Command Error] User: "Ahnaf#4346", Message: "sh!exec
```py
print("Oof")
```", Error: "AttributeError: 'SuperUser' object has no attribute 'logger'", Traceback: "Traceback (most recent call last):  File "C:\Users\HOME\AppData\Local\Programs\Python\Python38-32\lib\site-packages\lightbulb\command_handler.py", line 852, in process_commands_for_event    await self._invoke_command(command, context, positional_args, keyword_arg)  File "C:\Users\HOME\AppData\Local\Programs\Python\Python38-32\lib\site-packages\lightbulb\command_handler.py", line 784, in _invoke_command    await command.invoke(context, *args, **kwarg)  File "C:\Users\HOME\AppData\Local\Programs\Python\Python38-32\lib\site-packages\lightbulb\commands.py", line 88, in invoke    return await self._callback(instance, context, *new_args, **kwargs)  File "F:\Ahnaf's Folder\Shikamaru Bot\shikamaru\plugins\superuser.py", line 22, in execute    await body.run()  File "F:\Ahnaf's Folder\Shikamaru Bot\shikamaru\utils\code.py", line 46, in _execute    if logger := getattr(self.context.command.plugin, "logger"):lightbulb.errors.CommandInvocationError: AttributeError: 'SuperUser' object has no attribute 'logger'"
2020-09-28 15:50:28 [Command Error] User: "Ahnaf#4346", Message: "sh!exec
```py
print("Oof")
```", Error: "AttributeError: 'SuperUser' object has no attribute 'logger'", Traceback: "Traceback (most recent call last):  File "C:\Users\HOME\AppData\Local\Programs\Python\Python38-32\lib\site-packages\lightbulb\command_handler.py", line 852, in process_commands_for_event    await self._invoke_command(command, context, positional_args, keyword_arg)  File "C:\Users\HOME\AppData\Local\Programs\Python\Python38-32\lib\site-packages\lightbulb\command_handler.py", line 784, in _invoke_command    await command.invoke(context, *args, **kwarg)  File "C:\Users\HOME\AppData\Local\Programs\Python\Python38-32\lib\site-packages\lightbulb\commands.py", line 88, in invoke    return await self._callback(instance, context, *new_args, **kwargs)  File "F:\Ahnaf's Folder\Shikamaru Bot\shikamaru\plugins\superuser.py", line 22, in execute    await body.run()  File "F:\Ahnaf's Folder\Shikamaru Bot\shikamaru\utils\code.py", line 46, in _execute    if logger := getattr(self.context.command.plugin, "logger"):lightbulb.errors.CommandInvocationError: AttributeError: 'SuperUser' object has no attribute 'logger'"
2020-09-28 15:53:54 [Command Error] User: "Ahnaf#4346", Message: "sh!codefor SuperUser", Error: "NameError: name 'Plugin' is not defined", Traceback: "Traceback (most recent call last):  File "C:\Users\HOME\AppData\Local\Programs\Python\Python38-32\lib\site-packages\lightbulb\command_handler.py", line 852, in process_commands_for_event    await self._invoke_command(command, context, positional_args, keyword_arg)  File "C:\Users\HOME\AppData\Local\Programs\Python\Python38-32\lib\site-packages\lightbulb\command_handler.py", line 786, in _invoke_command    await command.invoke(context, *args)  File "C:\Users\HOME\AppData\Local\Programs\Python\Python38-32\lib\site-packages\lightbulb\commands.py", line 88, in invoke    return await self._callback(instance, context, *new_args, **kwargs)  File "F:\Ahnaf's Folder\Shikamaru Bot\shikamaru\plugins\superuser.py", line 71, in getcode    if isinstance(child, Plugin)lightbulb.errors.CommandInvocationError: NameError: name 'Plugin' is not defined"
2020-09-28 15:55:19 [Command Error] User: "Ahnaf#4346", Message: "sh!exec
```py
print()
```", Error: "AttributeError: 'SuperUser' object has no attribute 'logger'", Traceback: "Traceback (most recent call last):  File "C:\Users\HOME\AppData\Local\Programs\Python\Python38-32\lib\site-packages\lightbulb\command_handler.py", line 852, in process_commands_for_event    await self._invoke_command(command, context, positional_args, keyword_arg)  File "C:\Users\HOME\AppData\Local\Programs\Python\Python38-32\lib\site-packages\lightbulb\command_handler.py", line 784, in _invoke_command    await command.invoke(context, *args, **kwarg)  File "C:\Users\HOME\AppData\Local\Programs\Python\Python38-32\lib\site-packages\lightbulb\commands.py", line 88, in invoke    return await self._callback(instance, context, *new_args, **kwargs)  File "F:\Ahnaf's Folder\Shikamaru Bot\shikamaru\plugins\superuser.py", line 22, in execute    await body.run()  File "F:\Ahnaf's Folder\Shikamaru Bot\shikamaru\utils\code.py", line 46, in _execute    if logger := getattr(self.context.command.plugin, "logger"):lightbulb.errors.CommandInvocationError: AttributeError: 'SuperUser' object has no attribute 'logger'"
2020-09-28 16:03:52 [Command Error] User: "Ahnaf#4346", Message: "sh!exec
```py
print()
```", Error: "NameError: name 'command' is not defined", Traceback: "Traceback (most recent call last):  File "C:\Users\HOME\AppData\Local\Programs\Python\Python38-32\lib\site-packages\lightbulb\command_handler.py", line 852, in process_commands_for_event    await self._invoke_command(command, context, positional_args, keyword_arg)  File "C:\Users\HOME\AppData\Local\Programs\Python\Python38-32\lib\site-packages\lightbulb\command_handler.py", line 788, in _invoke_command    await command.invoke(context)  File "C:\Users\HOME\AppData\Local\Programs\Python\Python38-32\lib\site-packages\lightbulb\commands.py", line 88, in invoke    return await self._callback(instance, context, *new_args, **kwargs)  File "F:\Ahnaf's Folder\Shikamaru Bot\shikamaru\plugins\superuser.py", line 23, in code    code = ctx.message.content[len(command) + 1:]lightbulb.errors.CommandInvocationError: NameError: name 'command' is not defined"
2020-09-28 16:06:17 [Command Error] User: "Ahnaf#4346", Message: "sh!exec
```py
print()
```", Error: "AttributeError: 'SuperUser' object has no attribute 'eprint'", Traceback: "Traceback (most recent call last):  File "C:\Users\HOME\AppData\Local\Programs\Python\Python38-32\lib\site-packages\lightbulb\command_handler.py", line 852, in process_commands_for_event    await self._invoke_command(command, context, positional_args, keyword_arg)  File "C:\Users\HOME\AppData\Local\Programs\Python\Python38-32\lib\site-packages\lightbulb\command_handler.py", line 788, in _invoke_command    await command.invoke(context)  File "C:\Users\HOME\AppData\Local\Programs\Python\Python38-32\lib\site-packages\lightbulb\commands.py", line 88, in invoke    return await self._callback(instance, context, *new_args, **kwargs)  File "F:\Ahnaf's Folder\Shikamaru Bot\shikamaru\plugins\superuser.py", line 39, in code    "eprint": self.eprint,lightbulb.errors.CommandInvocationError: AttributeError: 'SuperUser' object has no attribute 'eprint'"
2020-09-28 16:08:02 [Command Error] User: "Ahnaf#4346", Message: "sh!exec
```py
print()
```", Error: "NameError: name 'io' is not defined", Traceback: "Traceback (most recent call last):  File "C:\Users\HOME\AppData\Local\Programs\Python\Python38-32\lib\site-packages\lightbulb\command_handler.py", line 852, in process_commands_for_event    await self._invoke_command(command, context, positional_args, keyword_arg)  File "C:\Users\HOME\AppData\Local\Programs\Python\Python38-32\lib\site-packages\lightbulb\command_handler.py", line 788, in _invoke_command    await command.invoke(context)  File "C:\Users\HOME\AppData\Local\Programs\Python\Python38-32\lib\site-packages\lightbulb\commands.py", line 88, in invoke    return await self._callback(instance, context, *new_args, **kwargs)  File "F:\Ahnaf's Folder\Shikamaru Bot\shikamaru\plugins\superuser.py", line 46, in code    stdout = io.StringIO()lightbulb.errors.CommandInvocationError: NameError: name 'io' is not defined"
2020-09-28 16:10:59 [Command Error] User: "Ahnaf#4346", Message: "sh!exec
```py
print()
```", Error: "AttributeError: 'Context' object has no attribute 'send'", Traceback: "Traceback (most recent call last):  File "C:\Users\HOME\AppData\Local\Programs\Python\Python38-32\lib\site-packages\lightbulb\command_handler.py", line 852, in process_commands_for_event    await self._invoke_command(command, context, positional_args, keyword_arg)  File "C:\Users\HOME\AppData\Local\Programs\Python\Python38-32\lib\site-packages\lightbulb\command_handler.py", line 788, in _invoke_command    await command.invoke(context)  File "C:\Users\HOME\AppData\Local\Programs\Python\Python38-32\lib\site-packages\lightbulb\commands.py", line 88, in invoke    return await self._callback(instance, context, *new_args, **kwargs)  File "F:\Ahnaf's Folder\Shikamaru Bot\shikamaru\plugins\superuser.py", line 52, in code    await ctx.send(stdout)lightbulb.errors.CommandInvocationError: AttributeError: 'Context' object has no attribute 'send'"
2020-09-28 16:45:05 [Command Error] User: "Ahnaf#4346", Message: "sh!info", Error: "info", Traceback: "Traceback (most recent call last):  File "C:\Users\HOME\AppData\Local\Programs\Python\Python38-32\lib\site-packages\lightbulb\command_handler.py", line 813, in process_commands_for_event    command = self._validate_command_exists(invoked_with)  File "C:\Users\HOME\AppData\Local\Programs\Python\Python38-32\lib\site-packages\lightbulb\command_handler.py", line 730, in _validate_command_exists    raise errors.CommandNotFound(invoked_with)lightbulb.errors.CommandNotFound: info"
2020-09-28 16:55:23 [Command Error] User: "thomm.o#8637", Message: "sh!ping", Error: "ForbiddenError: Forbidden 403: 'Missing Permissions' for https://discord.com/api/v6/channels/727982024660615198/messages", Traceback: "Traceback (most recent call last):  File "C:\Users\HOME\AppData\Local\Programs\Python\Python38-32\lib\site-packages\lightbulb\command_handler.py", line 852, in process_commands_for_event    await self._invoke_command(command, context, positional_args, keyword_arg)  File "C:\Users\HOME\AppData\Local\Programs\Python\Python38-32\lib\site-packages\lightbulb\command_handler.py", line 788, in _invoke_command    await command.invoke(context)  File "C:\Users\HOME\AppData\Local\Programs\Python\Python38-32\lib\site-packages\lightbulb\commands.py", line 88, in invoke    return await self._callback(instance, context, *new_args, **kwargs)  File "F:\Ahnaf's Folder\Shikamaru Bot\shikamaru\plugins\info.py", line 26, in ping    msg = await ctx.reply("Pinging...")  File "C:\Users\HOME\AppData\Local\Programs\Python\Python38-32\lib\site-packages\lightbulb\context.py", line 193, in reply    return await self.message.reply(*args, **kwargs)  File "C:\Users\HOME\AppData\Local\Programs\Python\Python38-32\lib\site-packages\hikari\messages.py", line 649, in reply    return await self.app.rest.create_message(  File "C:\Users\HOME\AppData\Local\Programs\Python\Python38-32\lib\site-packages\hikari\impl\rest.py", line 1053, in create_message    raw_response = await self._request(route, json=body)  File "C:\Users\HOME\AppData\Local\Programs\Python\Python38-32\lib\site-packages\hikari\impl\rest.py", line 600, in _request    await self._handle_error_response(response)  File "C:\Users\HOME\AppData\Local\Programs\Python\Python38-32\lib\site-packages\hikari\impl\rest.py", line 621, in _handle_error_response    raise await net.generate_error_response(response)lightbulb.errors.CommandInvocationError: ForbiddenError: Forbidden 403: 'Missing Permissions' for https://discord.com/api/v6/channels/727982024660615198/messages"
